Workbook

Sheet 01_Executive Summary
A1: LIBETEE KOREA ｜ スーツケース700個 大量入荷 投資審査
A2: 対象: 今後入荷予定700個への投資判断 ／ 審査日 2026-09-11 ／ A=投資委員会・B=経営者モード ／ 数値は 02_Assumptions と連動
A4: 【結論】
A5: 1. 700個の一括発注は、完売しても標準ケースで年間営業赤字（−1,268,328円）。数量そのものが損益分岐に届いていない。
A6: 2. 損益分岐は月78個＝年936個。700個／年では固定費を回収できない。
A7: 3. 投資額 約1,078万円・最大運転資金 約1,420万円は、過去9ヶ月の全支出（約417万円）の2.6〜3.4倍。実績販売データ無しでこの規模は承認できない。
A9: 【投資判断】
A10: 項目 | B10: 判定・数値 | E10: 根拠
A11: 投資判断（700個一括） | B11: NO GO | E11: 総合38.3点／即却下レンジ。完売しても標準ケースで年間赤字
A12: 投資判断（小ロット追加） | B12: 条件付きGO | E12: 100〜150個に縮小し、実績CPA・販売数を取得してから再審査
A13: 総合スコア | B13: 38.3 / 100 | E13: 18_Premortem & Score の12項目評価
A14: 投資可能上限 | B14: ¥2,200,000 | E14: 小ロット150個相当。700個には出さない（15_MVP Gate4まで）
A15: 最大損失許容額 | B15: ¥3,500,000 | E15: ★手元資金が未開示のため暫定。Gate0で確定させること
A16: 損益分岐売上（月） | B16: ='02_Assumptions'!$B$42 -> 2082600 | E16: 損益分岐数量×平均単価
A17: 損益分岐販売数（月） | B17: ='02_Assumptions'!$B$40 -> 78 | E17: 固定費 ÷ 平均限界利益
A18: 損益分岐販売数（年） | B18: ='02_Assumptions'!$B$41 -> 936 | E18: 700個／年では未達
A19: 目標CPA | B19: ='02_Assumptions'!$B$17 -> 4500 | E19: 客単価3万円×15%（社内基準）
A20: 許容CPA上限 | B20: ='02_Assumptions'!$B$18 -> 6000 | E20: 超えたら広告停止
A21: 現状の粗利率 | B21: ='02_Assumptions'!$B$37/'02_Assumptions'!$B$35 -> 0.37198502 | E21: EC物販の健全値50%に対し不足
A22: 必要粗利率 | B22: 50% 以上 | E22: 値上げ・原価低減・手数料低減のいずれかが必須
A24: 【最大の勝ち筋】
A25: 1. 700個発注による仕入単価の引き下げ。▲20%取れれば限界利益は5,432→8,512円、損益分岐は78→50個/月に改善する。ここが唯一の反転条件。
A26: 2. L（大型）の予約販売。在庫を持つ前に実需・CVRを実測できる、キャッシュを使わない唯一の検証手段。
A27: 3. レビュー資産とオーガニック流入の積み上げでCPAを下げる。CPA4,500→3,600で月58個でも黒字転換する。
A29: 【最大のリスク】
A30: 1. 在庫の不良化。標準ペースでも消化12ヶ月、悲観なら24ヶ月。悲観ケースの滞留352個は半額処分で約271万円の損失。
A31: 2. キャッシュ枯渇。最大運転資金 約1,420万円を回収前に先出しする。手元資金が未開示のまま発注はできない。
A32: 3. 手数料前提の崩壊。4%はモール手数料として異常に低い。実態が12%なら限界利益は5,432→3,472円に落ちる。
A34: 前提と限界
A35: 本審査は提供データ（支出実績2025.12-2026.08／原価S10万W・M15万W／売価S21,900・M27,900円／手数料4%／送料300円／社内CPA基準）に基づく。
A36: ★最重要不足データ：実績販売数・実績CPA/CVR・返品率・関税/国際送料/倉庫費・手元キャッシュ・700個のSKU内訳と数量割引後単価・リピート率。
A37: 為替0.11円/ウォン、L価格33,900円・原価20万W、ミックスS40:M40:L20 は仮定値。02_Assumptions で変更すると全シートが再計算されます。

Sheet 02_Assumptions
A1: 前提条件（Assumptions）— 全シートはここを参照
A2: 黄色セル＝入力欄。ここを書き換えると 05/06/07/10/11/12/13 が自動再計算されます。確度: 確定=実データ／仮定=分析用に置いた値／★要確認=判断を左右する未確認値
A4: 項目 | B4: 値 | C4: 単位 | D4: 確度 | E4: 根拠・リスク
A5: 為替レート | B5: 0.11 | C5: 円/ウォン | D5: 仮定 | E5: 実レートで要更新。±10%で限界利益が±1,540円動く
A6: 売価 S | B6: 21900 | C6: 円 | D6: 確定 | E6: ご指定
A7: 売価 M | B7: 27900 | C7: 円 | D7: 確定 | E7: ご指定
A8: 売価 L | B8: 33900 | C8: 円 | D8: 仮定 | E8: 未指定。S→Mの刻み+6,000円から推定
A9: 仕入原価 S | B9: 100000 | C9: ウォン | D9: 確定 | E9: スーツケース_仕入状況
A10: 仕入原価 M | B10: 150000 | C10: ウォン | D10: 確定 | E10: スーツケース_仕入状況
A11: 仕入原価 L | B11: 200000 | C11: ウォン | D11: 仮定 | E11: 未指定。S→Mの刻み+50,000Wから推定
A12: モール/決済手数料率 | B12: 0.04 | C12: — | D12: ★要確認 | E12: ★楽天・Amazonは通常10〜15%。4%は自社EC/PGのみの水準
A13: 送料（自社負担） | B13: 300 | C13: 円/個 | D13: 確定 | E13: ご指定。大型商品のため実額要検証
A14: 関税・国際送料・倉庫費 | B14: 0 | C14: 円/個 | D14: ★要確認 | E14: ★未算入。+1,000円で損益分岐は78→95個/月
A15: 返品引当 | B15: 0 | C15: 円/個 | D15: ★要確認 | E15: ★未算入。EC平均で売価の2〜5%
A16: ポイント/クーポン負担 | B16: 0 | C16: 円/個 | D16: ★要確認 | E16: ★未算入。楽天SPU等で実質3〜10%
... A31: 入金サイト | B31: 30 | C31: 日 | D31: 仮定 | E31: モール締め日基準
A32: 派生値（自動計算）
A33: 固定費（予想）円/月 | B33: ='02_Assumptions'!$B$19*'02_Assumptions'!$B$5 -> 420750 | D33: 算出 | E33: ウォン→円換算
A34: 固定費（実績平均）円/月 | B34: ='02_Assumptions'!$B$20*'02_Assumptions'!$B$5 -> 462922.13 | D34: 算出 | E34: 悲観ケースで使用
A35: MIX 平均売価 | B35: ='02_Assumptions'!$B$21*'02_Assumptions'!$B$6+'02_Assumptions'!$B$22*'02_Assumptions'!$B$7+'02_Assumptions'!$B$23*'02_Assumptions'!$B$8 -> 26700 | D35: 算出 | E35: ミックス加重平均
A36: MIX 平均原価（円） | B36: =('02_Assumptions'!$B$21*'02_Assumptions'!$B$9+'02_Assumptions'!$B$22*'02_Assumptions'!$B$10+'02_Assumptions'!$B$23*'02_Assumptions'!$B$11)*'02_Assumptions'!$B$5 -> 15400 | D36: 算出
A37: MIX 粗利/個 | B37: =$B$35-$B$35*'02_Assumptions'!$B$12-'02_Assumptions'!$B$13-$B$36-'02_Assumptions'!$B$14-'02_Assumptions'!$B$15-'02_Assumptions'!$B$16 -> 9932 | D37: 算出 | E37: 売価−手数料−送料−原価−追加費
A38: MIX 限界利益/個（@目標CPA） | B38: =$B$37-'02_Assumptions'!$B$17 -> 5432 | D38: 算出 | E38: 粗利−広告CPA
A39: MIX 限界利益率 | B39: =$B$38/$B$35 -> 0.20344569 | D39: 算出
A40: 損益分岐 販売数/月 | B40: =ROUNDUP($B$33/$B$38,0) -> 78 | D40: 算出 | E40: 固定費÷限界利益
A41: 損益分岐 販売数/年 | B41: =$B$40*12 -> 936 | D41: 算出
A42: 損益分岐 売上/月 | B42: =$B$40*$B$35 -> 2082600 | D42: 算出
A43: 標準ケース 月販売数 | B43: =ROUND('02_Assumptions'!$B$24/12,0) -> 58 | D43: 算出 | E43: 700個を12ヶ月で消化する前提
A44: 700個 仕入原価（円） | B44: =('02_Assumptions'!$B$21*'02_Assumptions'!$B$9+'02_Assumptions'!$B$22*'02_Assumptions'!$B$10+'02_Assumptions'!$B$23*'02_Assumptions'!$B$11)*'02_Assumptions'!$B$24*'02_Assumptions'!$B$5 -> 10780000 | D44: 算出 | E44: ミックス加重
A45: 注記
A46: ★要確認（赤）＝この値が変わると投資判断そのものが変わる「最重要不足データ」。
A47: 青字＝入力値、黒太字＝自動計算。黄色セルを書き換えれば全シートが連動して再計算されます。
A48: 未提出の重要データ：実績販売数／実績CPA・CVR／返品率／手元キャッシュ／700個のSKU内訳と数量割引後単価／リピート率。

Sheet 03_Market
A1: 市場分析（TAM / SAM / SOM）
A2: ★市場データ未提出。数値を捏造せず「埋めるべき枠」と調査方法を提示する。
A4: 区分 | B4: 定義 | C4: 規模 | D4: 出典 | E4: 調査方法・注記
A5: TAM | B5: 日本の旅行用スーツケース市場全体 | C5: 要調査 | D5: — | E5: 経産省 生産動態統計／矢野経済・富士経済／インバウンド統計
A6: SAM | B6: EC流通・価格帯2〜3万円 | C6: 要調査 | D6: — | E6: 楽天/Amazonカテゴリ上位100SKUの推定月販×単価を積み上げ
A7: SOM | B7: 自社が12ヶ月で獲得可能な数量 | C7: ='02_Assumptions'!$B$41 -> 936 | D7: 自社試算 | E7: 損益分岐から逆算した必要数量。市場から取れる保証はない
A8: 市場成長率 | B8: — | C8: 要調査 | D8: — | E8: コロナ後の旅行需要回復は一巡。横ばい〜微増を疑うべき
A9: 検索需要 | B9: 「スーツケース Mサイズ」等 | C9: 要調査 | D9: — | E9: Googleキーワードプランナー／楽天サジェスト／Amazonブランド分析
A10: 季節性 | B10: GW前・夏休み前・年末年始前 | C10: 要調査 | D10: — | E10: 閑散期の在庫滞留リスクを発注量に織り込むこと
A12: A｜投資委員会の指摘
A13: ・市場が大きいことと自社が取れることは別問題。TAMは判断材料にしない。
A14: ・スーツケース市場は成熟・レッドオーシャン。価格競争が常態で、差別化なき中価格帯が最も苦しい。
A15: ・2〜3万円帯はブランド勢（サムソナイト等）と廉価勢（無印・ニトリ・ノーブランド）に挟まれる。真ん中は最も選ばれにくい。
A16: ・「競合がいない」ではなく「その価格帯で勝っているプレイヤーの実売上」を測ること。

Sheet 04_Competitor
A1: 競合分析
A2: ★競合データ未提出。枠と観点を提示。楽天/Amazonランキング・レビュー数・価格の実データで埋めること。
A4: 競合区分 | B4: 想定プレイヤー | C4: 価格帯 | D4: レビュー数 | E4: 推定月販 | F4: 評価観点
A5: 直接競合 | B5: 同価格帯ECブランド | C5: 2〜3万円 | D5: 要調査 | E5: 要調査 | F5: レビュー数＝参入障壁。1,000件超の先行者に後発が勝つのは困難
A6: 直接競合 | B6: ノーブランド廉価 | C6: 0.8〜1.5万円 | D6: 要調査 | E6: 要調査 | F6: 価格勝負に引き込まれると粗利37%が即崩壊
A7: 間接競合 | B7: 大手ブランド | C7: 3〜8万円 | D7: 要調査 | E7: 要調査 | F7: ブランド指名検索を持つ。広告で正面衝突するとCPAが上がる
A8: 間接競合 | B8: 小売（無印・ニトリ・量販） | C8: 1〜3万円 | D8: — | E8: — | F8: 実店舗で触って買える。EC単独の弱点が出る
A9: 代替手段 | B9: レンタル | C9: 2,000〜8,000円/回 | D9: — | E9: — | F9: 年1回しか旅行しない層はレンタルに流れる
A10: 代替手段 | B10: 買わない／借りる | C10: ¥0 | D10: — | E10: — | F10: Vitamin商材の宿命。購入を先送りされる
A12: 競合が自社をコピーした場合
A13: ・スーツケースは意匠以外に参入障壁がほぼない。OEM元が同じなら競合も同じ商品を出せる。
A14: ・自社が広告で需要を掘り起こした瞬間、同型番の廉価版が相乗りしてくる構造。
A15: ・防御策は「レビュー数」「ブランド想起」「独自機能の意匠登録」の3つのみ。現状いずれも未確認。

Sheet 05_Pricing
A1: 価格設計と値引き耐性
A2: 売価S/Mは確定、Lは仮定。値引き耐性＝どこまで下げると1個売るごとに赤字になるか
A4: SKU | B4: 売価 | C4: 原価(W) | D4: 原価(円) | E4: 粗利 | F4: 粗利率 | G4: 限界益@目標CPA | H4: 限界益@許容CPA | L4: 注記
A5: S | B5: ='02_Assumptions'!$B$6 -> 21900 | C5: ='02_Assumptions'!$B$9 -> 100000 | D5: ='02_Assumptions'!$B$9*'02_Assumptions'!$B$5 -> 11000 | E5: =B5-B5*'02_Assumptions'!$B$12-'02_Assumptions'!$B$13-D5-'02_Assumptions'!$B$14-'02_Assumptions'!$B$15-'02_Assumptions'!$B$16 -> 9724 | F5: =E5/B5 -> 0.44401826 | G5: =E5-'02_Assumptions'!$B$17 -> 5224 | H5: =E5-'02_Assumptions'!$B$18 -> 3724 | L5: 確定
A6: M | B6: ='02_Assumptions'!$B$7 -> 27900 | C6: ='02_Assumptions'!$B$10 -> 150000 | D6: ='02_Assumptions'!$B$10*'02_Assumptions'!$B$5 -> 16500 | E6: =B6-B6*'02_Assumptions'!$B$12-'02_Assumptions'!$B$13-D6-'02_Assumptions'!$B$14-'02_Assumptions'!$B$15-'02_Assumptions'!$B$16 -> 9984 | F6: =E6/B6 -> 0.35784946 | G6: =E6-'02_Assumptions'!$B$17 -> 5484 | H6: =E6-'02_Assumptions'!$B$18 -> 3984 | L6: 確定
A7: L | B7: ='02_Assumptions'!$B$8 -> 33900 | C7: ='02_Assumptions'!$B$11 -> 200000 | D7: ='02_Assumptions'!$B$11*'02_Assumptions'!$B$5 -> 22000 | E7: =B7-B7*'02_Assumptions'!$B$12-'02_Assumptions'!$B$13-D7-'02_Assumptions'!$B$14-'02_Assumptions'!$B$15-'02_Assumptions'!$B$16 -> 10244 | F7: =E7/B7 -> 0.30218289 | G7: =E7-'02_Assumptions'!$B$17 -> 5744 | H7: =E7-'02_Assumptions'!$B$18 -> 4244 | L7: ★売価・原価とも仮定
A9: 値引き耐性（@目標CPA4,500での限界利益）
A10: SKU | B10: 定価 | C10: ▲5% | D10: ▲10% | E10: ▲15% | F10: ▲20% | G10: ▲25% | H10: 限界益ゼロ点
A11: S | B11: =$B$5*(1-0)-$B$5*(1-0)*'02_Assumptions'!$B$12-'02_Assumptions'!$B$13-$D$5-'02_Assumptions'!$B$14-'02_Assumptions'!$B$15-'02_Assumptions'!$B$16-'02_Assumptions'!$B$17 -> 5224 | C11: =$B$5*(1-0.05)-$B$5*(1-0.05)*'02_Assumptions'!$B$12-'02_Assumptions'!$B$13-$D$5-'02_Assumptions'!$B$14-'02_Assumptions'!$B$15-'02_Assumptions'!$B$16-'02_Assumptions'!$B$17 -> 4172.8 | D11: =$B$5*(1-0.1)-$B$5*(1-0.1)*'02_Assumptions'!$B$12-'02_Assumptions'!$B$13-$D$5-'02_Assumptions'!$B$14-'02_Assumptions'!$B$15-'02_Assumptions'!$B$16-'02_Assumptions'!$B$17 -> 3121.6 | E11: =$B$5*(1-0.15)-$B$5*(1-0.15)*'02_Assumptions'!$B$12-'02_Assumptions'!$B$13-$D$5-'02_Assumptions'!$B$14-'02_Assumptions'!$B$15-'02_Assumptions'!$B$16-'02_Assumptions'!$B$17 -> 2070.4 | F11: =$B$5*(1-0.2)-$B$5*(1-0.2)*'02_Assumptions'!$B$12-'02_Assumptions'!$B$13-$D$5-'02_Assumptions'!$B$14-'02_Assumptions'!$B$15-'02_Assumptions'!$B$16-'02_Assumptions'!$B$17 -> 1019.2 | G11: =$B$5*(1-0.25)-$B$5*(1-0.25)*'02_Assumptions'!$B$12-'02_Assumptions'!$B$13-$D$5-'02_Assumptions'!$B$14-'02_Assumptions'!$B$15-'02_Assumptions'!$B$16-'02_Assumptions'!$B$17 -> -32 | H11: 0.249
A12: M | B12: =$B$6*(1-0)-$B$6*(1-0)*'02_Assumptions'!$B$12-'02_Assumptions'!$B$13-$D$6-'02_Assumptions'!$B$14-'02_Assumptions'!$B$15-'02_Assumptions'!$B$16-'02_Assumptions'!$B$17 -> 5484 | C12: =$B$6*(1-0.05)-$B$6*(1-0.05)*'02_Assumptions'!$B$12-'02_Assumptions'!$B$13-$D$6-'02_Assumptions'!$B$14-'02_Assumptions'!$B$15-'02_Assumptions'!$B$16-'02_Assumptions'!$B$17 -> 4144.8 | D12: =$B$6*(1-0.1)-$B$6*(1-0.1)*'02_Assumptions'!$B$12-'02_Assumptions'!$B$13-$D$6-'02_Assumptions'!$B$14-'02_Assumptions'!$B$15-'02_Assumptions'!$B$16-'02_Assumptions'!$B$17 -> 2805.6 | E12: =$B$6*(1-0.15)-$B$6*(1-0.15)*'02_Assumptions'!$B$12-'02_Assumptions'!$B$13-$D$6-'02_Assumptions'!$B$14-'02_Assumptions'!$B$15-'02_Assumptions'!$B$16-'02_Assumptions'!$B$17 -> 1466.4 | F12: =$B$6*(1-0.2)-$B$6*(1-0.2)*'02_Assumptions'!$B$12-'02_Assumptions'!$B$13-$D$6-'02_Assumptions'!$B$14-'02_Assumptions'!$B$15-'02_Assumptions'!$B$16-'02_Assumptions'!$B$17 -> 127.2 | G12: =$B$6*(1-0.25)-$B$6*(1-0.25)*'02_Assumptions'!$B$12-'02_Assumptions'!$B$13-$D$6-'02_Assumptions'!$B$14-'02_Assumptions'!$B$15-'02_Assumptions'!$B$16-'02_Assumptions'!$B$17 -> -1212 | H12: 0.205
A13: L | B13: =$B$7*(1-0)-$B$7*(1-0)*'02_Assumptions'!$B$12-'02_Assumptions'!$B$13-$D$7-'02_Assumptions'!$B$14-'02_Assumptions'!$B$15-'02_Assumptions'!$B$16-'02_Assumptions'!$B$17 -> 5744 | C13: =$B$7*(1-0.05)-$B$7*(1-0.05)*'02_Assumptions'!$B$12-'02_Assumptions'!$B$13-$D$7-'02_Assumptions'!$B$14-'02_Assumptions'!$B$15-'02_Assumptions'!$B$16-'02_Assumptions'!$B$17 -> 4116.8 | D13: =$B$7*(1-0.1)-$B$7*(1-0.1)*'02_Assumptions'!$B$12-'02_Assumptions'!$B$13-$D$7-'02_Assumptions'!$B$14-'02_Assumptions'!$B$15-'02_Assumptions'!$B$16-'02_Assumptions'!$B$17 -> 2489.6 | E13: =$B$7*(1-0.15)-$B$7*(1-0.15)*'02_Assumptions'!$B$12-'02_Assumptions'!$B$13-$D$7-'02_Assumptions'!$B$14-'02_Assumptions'!$B$15-'02_Assumptions'!$B$16-'02_Assumptions'!$B$17 -> 862.4 | F13: =$B$7*(1-0.2)-$B$7*(1-0.2)*'02_Assumptions'!$B$12-'02_Assumptions'!$B$13-$D$7-'02_Assumptions'!$B$14-'02_Assumptions'!$B$15-'02_Assumptions'!$B$16-'02_Assumptions'!$B$17 -> -764.8 | G13: =$B$7*(1-0.25)-$B$7*(1-0.25)*'02_Assumptions'!$B$12-'02_Assumptions'!$B$13-$D$7-'02_Assumptions'!$B$14-'02_Assumptions'!$B$15-'02_Assumptions'!$B$16-'02_Assumptions'!$B$17 -> -2392 | H13: 0.177
A14: 注記
A15: S は約▲25%、M/L は約▲20%で限界利益がゼロ。セール耐性は低い。
A16: クーポン・ポイント還元は実質値引き。楽天SPU等で10%相当を負担すると M/L は赤字圏に入る。
A17: ※ 02_Assumptions の「ポイント/クーポン負担」を実額で入れれば、この表に自動反映されます。

Sheet 06_Unit Economics
A1: ユニットエコノミクス（1個あたり）
A2: 黄色の0円列は★未算入＝現在の利益は過大評価。02_Assumptions で実額を入れると全て連動します。
A4: SKU | B4: 売価 | C4: 仕入原価 | D4: 国際送料/関税/倉庫 | E4: 返品引当 | F4: ポイント | G4: 国内送料 | H4: モール/決済手数料 | L4: 広告CPA | M4: 限界利益 | N4: 限界利益率 | O4: 注記
A5: S | B5: ='02_Assumptions'!$B$6 -> 21900 | C5: ='02_Assumptions'!$B$9*'02_Assumptions'!$B$5 -> 11000 | D5: ='02_Assumptions'!$B$14 -> 0 | E5: ='02_Assumptions'!$B$15 -> 0 | F5: ='02_Assumptions'!$B$16 -> 0 | G5: ='02_Assumptions'!$B$13 -> 300 | H5: =B5*'02_Assumptions'!$B$12 -> 876 | L5: ='02_Assumptions'!$B$17 -> 4500 | M5: =B5-C5-D5-E5-F5-G5-H5-L5 -> 5224 | N5: =M5/B5 -> 0.23853881 | O5: ★未算入項目あり
A6: M | B6: ='02_Assumptions'!$B$7 -> 27900 | C6: ='02_Assumptions'!$B$10*'02_Assumptions'!$B$5 -> 16500 | D6: ='02_Assumptions'!$B$14 -> 0 | E6: ='02_Assumptions'!$B$15 -> 0 | F6: ='02_Assumptions'!$B$16 -> 0 | G6: ='02_Assumptions'!$B$13 -> 300 | H6: =B6*'02_Assumptions'!$B$12 -> 1116 | L6: ='02_Assumptions'!$B$17 -> 4500 | M6: =B6-C6-D6-E6-F6-G6-H6-L6 -> 5484 | N6: =M6/B6 -> 0.19655914 | O6: ★未算入項目あり
A7: L | B7: ='02_Assumptions'!$B$8 -> 33900 | C7: ='02_Assumptions'!$B$11*'02_Assumptions'!$B$5 -> 22000 | D7: ='02_Assumptions'!$B$14 -> 0 | E7: ='02_Assumptions'!$B$15 -> 0 | F7: ='02_Assumptions'!$B$16 -> 0 | G7: ='02_Assumptions'!$B$13 -> 300 | H7: =B7*'02_Assumptions'!$B$12 -> 1356 | L7: ='02_Assumptions'!$B$17 -> 4500 | M7: =B7-C7-D7-E7-F7-G7-H7-L7 -> 5744 | N7: =M7/B7 -> 0.16943953 | O7: ★未算入項目あり
A8: MIX | B8: ='02_Assumptions'!$B$35 -> 26700 | C8: ='02_Assumptions'!$B$36 -> 15400 | D8: ='02_Assumptions'!$B$14 -> 0 | E8: ='02_Assumptions'!$B$15 -> 0 | F8: ='02_Assumptions'!$B$16 -> 0 | G8: ='02_Assumptions'!$B$13 -> 300 | H8: =B8*'02_Assumptions'!$B$12 -> 1068 | L8: ='02_Assumptions'!$B$17 -> 4500 | M8: ='02_Assumptions'!$B$38 -> 5432 | N8: ='02_Assumptions'!$B$39 -> 0.20344569 | O8: 仮定ミックス S40:M40:L20
A10: 感応度①：未算入コストを入れた場合（MIX・目標CPA）
A11: 追加コスト/個 | B11: 限界利益 | C11: 限界利益率 | D11: 損益分岐(個/月)
A12: 0 | B12: ='02_Assumptions'!$B$38-A12 -> 5432 | C12: =B12/'02_Assumptions'!$B$35 -> 0.20344569 | D12: =IF(B12<=0,"—",ROUNDUP('02_Assumptions'!$B$33/B12,0)) -> 78
A13: 500 | B13: ='02_Assumptions'!$B$38-A13 -> 4932 | C13: =B13/'02_Assumptions'!$B$35 -> 0.1847191 | D13: =IF(B13<=0,"—",ROUNDUP('02_Assumptions'!$B$33/B13,0)) -> 86
A14: 1000 | B14: ='02_Assumptions'!$B$38-A14 -> 4432 | C14: =B14/'02_Assumptions'!$B$35 -> 0.16599251 | D14: =IF(B14<=0,"—",ROUNDUP('02_Assumptions'!$B$33/B14,0)) -> 95
A15: 1500 | B15: ='02_Assumptions'!$B$38-A15 -> 3932 | C15: =B15/'02_Assumptions'!$B$35 -> 0.14726592 | D15: =IF(B15<=0,"—",ROUNDUP('02_Assumptions'!$B$33/B15,0)) -> 108
A16: 2000 | B16: ='02_Assumptions'!$B$38-A16 -> 3432 | C16: =B16/'02_Assumptions'!$B$35 -> 0.12853933 | D16: =IF(B16<=0,"—",ROUNDUP('02_Assumptions'!$B$33/B16,0)) -> 123
A17: 3000 | B17: ='02_Assumptions'!$B$38-A17 -> 2432 | C17: =B17/'02_Assumptions'!$B$35 -> 0.091086142 | D17: =IF(B17<=0,"—",ROUNDUP('02_Assumptions'!$B$33/B17,0)) -> 174
A19: 感応度②：モール手数料率（S・目標CPA）
A20: 手数料率 | B20: 粗利 | C20: 粗利率 | D20: 限界利益 | E20: 限界利益率
A21: 0.04 | B21: ='02_Assumptions'!$B$6-'02_Assumptions'!$B$6*A21-'02_Assumptions'!$B$13-'02_Assumptions'!$B$9*'02_Assumptions'!$B$5-'02_Assumptions'!$B$14-'02_Assumptions'!$B$15-'02_Assumptions'!$B$16 -> 9724 | C21: =B21/'02_Assumptions'!$B$6 -> 0.44401826 | D21: =B21-'02_Assumptions'!$B$17 -> 5224 | E21: =D21/'02_Assumptions'!$B$6 -> 0.23853881
A22: 0.08 | B22: ='02_Assumptions'!$B$6-'02_Assumptions'!$B$6*A22-'02_Assumptions'!$B$13-'02_Assumptions'!$B$9*'02_Assumptions'!$B$5-'02_Assumptions'!$B$14-'02_Assumptions'!$B$15-'02_Assumptions'!$B$16 -> 8848 | C22: =B22/'02_Assumptions'!$B$6 -> 0.40401826 | D22: =B22-'02_Assumptions'!$B$17 -> 4348 | E22: =D22/'02_Assumptions'!$B$6 -> 0.19853881
A23: 0.1 | B23: ='02_Assumptions'!$B$6-'02_Assumptions'!$B$6*A23-'02_Assumptions'!$B$13-'02_Assumptions'!$B$9*'02_Assumptions'!$B$5-'02_Assumptions'!$B$14-'02_Assumptions'!$B$15-'02_Assumptions'!$B$16 -> 8410 | C23: =B23/'02_Assumptions'!$B$6 -> 0.38401826 | D23: =B23-'02_Assumptions'!$B$17 -> 3910 | E23: =D23/'02_Assumptions'!$B$6 -> 0.17853881
A24: 0.12 | B24: ='02_Assumptions'!$B$6-'02_Assumptions'!$B$6*A24-'02_Assumptions'!$B$13-'02_Assumptions'!$B$9*'02_Assumptions'!$B$5-'02_Assumptions'!$B$14-'02_Assumptions'!$B$15-'02_Assumptions'!$B$16 -> 7972 | C24: =B24/'02_Assumptions'!$B$6 -> 0.36401826 | D24: =B24-'02_Assumptions'!$B$17 -> 3472 | E24: =D24/'02_Assumptions'!$B$6 -> 0.15853881
A25: 0.15 | B25: ='02_Assumptions'!$B$6-'02_Assumptions'!$B$6*A25-'02_Assumptions'!$B$13-'02_Assumptions'!$B$9*'02_Assumptions'!$B$5-'02_Assumptions'!$B$14-'02_Assumptions'!$B$15-'02_Assumptions'!$B$16 -> 7315 | C25: =B25/'02_Assumptions'!$B$6 -> 0.33401826 | D25: =B25-'02_Assumptions'!$B$17 -> 2815 | E25: =D25/'02_Assumptions'!$B$6 -> 0.12853881
A26: 注記
A27: LTV/CAC：スーツケースは買替サイクル5〜10年の低頻度商材。LTV≒初回購入額として評価する。
A28: 売上ベース LTV/CAC＝26,700÷4,500＝5.9倍。ただし限界利益ベースでは 5,432÷4,500＝1.2倍しかない（健全値3倍）。
A29: 回収期間：1個単位では即時。ただし700個ロットでは全量販売完了まで12ヶ月以上（12_Inventory参照）。
A30: ★未算入コストを1,000円/個入れるだけで、損益分岐は78→95個/月に悪化する。

Sheet 07_Sales Forecast
A1: 販売計画（12ヶ月・標準ケース）
A2: ★販売実績が未提出のため、「700個を12ヶ月で消化」＝月58個を標準として置いた計画値。実績ではない。
A4: 月 | B4: 販売数 | C4: 平均単価 | D4: 売上 | E4: 原価計 | F4: 粗利 | G4: 広告費 | H4: 限界利益 | I4: 固定費 | J4: 営業利益 | K4: 注記
A5: M1 | B5: ='02_Assumptions'!$B$43 -> 58 | C5: ='02_Assumptions'!$B$35 -> 26700 | D5: =B5*C5 -> 1548600 | E5: =B5*('02_Assumptions'!$B$36+'02_Assumptions'!$B$13+'02_Assumptions'!$B$35*'02_Assumptions'!$B$12+'02_Assumptions'!$B$14+'02_Assumptions'!$B$15+'02_Assumptions'!$B$16) -> 972544 | F5: =D5-E5 -> 576056 | G5: =B5*'02_Assumptions'!$B$17 -> 261000 | H5: =F5-G5 -> 315056 | I5: ='02_Assumptions'!$B$33 -> 420750 | J5: =H5-I5 -> -105694 | K5: 月58個＝700個÷12ヶ月
A6: M2 | B6: ='02_Assumptions'!$B$43 -> 58 | C6: ='02_Assumptions'!$B$35 -> 26700 | D6: =B6*C6 -> 1548600 | E6: =B6*('02_Assumptions'!$B$36+'02_Assumptions'!$B$13+'02_Assumptions'!$B$35*'02_Assumptions'!$B$12+'02_Assumptions'!$B$14+'02_Assumptions'!$B$15+'02_Assumptions'!$B$16) -> 972544 | F6: =D6-E6 -> 576056 | G6: =B6*'02_Assumptions'!$B$17 -> 261000 | H6: =F6-G6 -> 315056 | I6: ='02_Assumptions'!$B$33 -> 420750 | J6: =H6-I6 -> -105694
A7: M3 | B7: ='02_Assumptions'!$B$43 -> 58 | C7: ='02_Assumptions'!$B$35 -> 26700 | D7: =B7*C7 -> 1548600 | E7: =B7*('02_Assumptions'!$B$36+'02_Assumptions'!$B$13+'02_Assumptions'!$B$35*'02_Assumptions'!$B$12+'02_Assumptions'!$B$14+'02_Assumptions'!$B$15+'02_Assumptions'!$B$16) -> 972544 | F7: =D7-E7 -> 576056 | G7: =B7*'02_Assumptions'!$B$17 -> 261000 | H7: =F7-G7 -> 315056 | I7: ='02_Assumptions'!$B$33 -> 420750 | J7: =H7-I7 -> -105694
A8: M4 | B8: ='02_Assumptions'!$B$43 -> 58 | C8: ='02_Assumptions'!$B$35 -> 26700 | D8: =B8*C8 -> 1548600 | E8: =B8*('02_Assumptions'!$B$36+'02_Assumptions'!$B$13+'02_Assumptions'!$B$35*'02_Assumptions'!$B$12+'02_Assumptions'!$B$14+'02_Assumptions'!$B$15+'02_Assumptions'!$B$16) -> 972544 | F8: =D8-E8 -> 576056 | G8: =B8*'02_Assumptions'!$B$17 -> 261000 | H8: =F8-G8 -> 315056 | I8: ='02_Assumptions'!$B$33 -> 420750 | J8: =H8-I8 -> -105694
A9: M5 | B9: ='02_Assumptions'!$B$43 -> 58 | C9: ='02_Assumptions'!$B$35 -> 26700 | D9: =B9*C9 -> 1548600 | E9: =B9*('02_Assumptions'!$B$36+'02_Assumptions'!$B$13+'02_Assumptions'!$B$35*'02_Assumptions'!$B$12+'02_Assumptions'!$B$14+'02_Assumptions'!$B$15+'02_Assumptions'!$B$16) -> 972544 | F9: =D9-E9 -> 576056 | G9: =B9*'02_Assumptions'!$B$17 -> 261000 | H9: =F9-G9 -> 315056 | I9: ='02_Assumptions'!$B$33 -> 420750 | J9: =H9-I9 -> -105694
A10: M6 | B10: ='02_Assumptions'!$B$43 -> 58 | C10: ='02_Assumptions'!$B$35 -> 26700 | D10: =B10*C10 -> 1548600 | E10: =B10*('02_Assumptions'!$B$36+'02_Assumptions'!$B$13+'02_Assumptions'!$B$35*'02_Assumptions'!$B$12+'02_Assumptions'!$B$14+'02_Assumptions'!$B$15+'02_Assumptions'!$B$16) -> 972544 | F10: =D10-E10 -> 576056 | G10: =B10*'02_Assumptions'!$B$17 -> 261000 | H10: =F10-G10 -> 315056 | I10: ='02_Assumptions'!$B$33 -> 420750 | J10: =H10-I10 -> -105694
A11: M7 | B11: ='02_Assumptions'!$B$43 -> 58 | C11: ='02_Assumptions'!$B$35 -> 26700 | D11: =B11*C11 -> 1548600 | E11: =B11*('02_Assumptions'!$B$36+'02_Assumptions'!$B$13+'02_Assumptions'!$B$35*'02_Assumptions'!$B$12+'02_Assumptions'!$B$14+'02_Assumptions'!$B$15+'02_Assumptions'!$B$16) -> 972544 | F11: =D11-E11 -> 576056 | G11: =B11*'02_Assumptions'!$B$17 -> 261000 | H11: =F11-G11 -> 315056 | I11: ='02_Assumptions'!$B$33 -> 420750 | J11: =H11-I11 -> -105694
A12: M8 | B12: ='02_Assumptions'!$B$43 -> 58 | C12: ='02_Assumptions'!$B$35 -> 26700 | D12: =B12*C12 -> 1548600 | E12: =B12*('02_Assumptions'!$B$36+'02_Assumptions'!$B$13+'02_Assumptions'!$B$35*'02_Assumptions'!$B$12+'02_Assumptions'!$B$14+'02_Assumptions'!$B$15+'02_Assumptions'!$B$16) -> 972544 | F12: =D12-E12 -> 576056 | G12: =B12*'02_Assumptions'!$B$17 -> 261000 | H12: =F12-G12 -> 315056 | I12: ='02_Assumptions'!$B$33 -> 420750 | J12: =H12-I12 -> -105694
A13: M9 | B13: ='02_Assumptions'!$B$43 -> 58 | C13: ='02_Assumptions'!$B$35 -> 26700 | D13: =B13*C13 -> 1548600 | E13: =B13*('02_Assumptions'!$B$36+'02_Assumptions'!$B$13+'02_Assumptions'!$B$35*'02_Assumptions'!$B$12+'02_Assumptions'!$B$14+'02_Assumptions'!$B$15+'02_Assumptions'!$B$16) -> 972544 | F13: =D13-E13 -> 576056 | G13: =B13*'02_Assumptions'!$B$17 -> 261000 | H13: =F13-G13 -> 315056 | I13: ='02_Assumptions'!$B$33 -> 420750 | J13: =H13-I13 -> -105694
A14: M10 | B14: ='02_Assumptions'!$B$43 -> 58 | C14: ='02_Assumptions'!$B$35 -> 26700 | D14: =B14*C14 -> 1548600 | E14: =B14*('02_Assumptions'!$B$36+'02_Assumptions'!$B$13+'02_Assumptions'!$B$35*'02_Assumptions'!$B$12+'02_Assumptions'!$B$14+'02_Assumptions'!$B$15+'02_Assumptions'!$B$16) -> 972544 | F14: =D14-E14 -> 576056 | G14: =B14*'02_Assumptions'!$B$17 -> 261000 | H14: =F14-G14 -> 315056 | I14: ='02_Assumptions'!$B$33 -> 420750 | J14: =H14-I14 -> -105694
A15: M11 | B15: ='02_Assumptions'!$B$43 -> 58 | C15: ='02_Assumptions'!$B$35 -> 26700 | D15: =B15*C15 -> 1548600 | E15: =B15*('02_Assumptions'!$B$36+'02_Assumptions'!$B$13+'02_Assumptions'!$B$35*'02_Assumptions'!$B$12+'02_Assumptions'!$B$14+'02_Assumptions'!$B$15+'02_Assumptions'!$B$16) -> 972544 | F15: =D15-E15 -> 576056 | G15: =B15*'02_Assumptions'!$B$17 -> 261000 | H15: =F15-G15 -> 315056 | I15: ='02_Assumptions'!$B$33 -> 420750 | J15: =H15-I15 -> -105694
A16: M12 | B16: ='02_Assumptions'!$B$43 -> 58 | C16: ='02_Assumptions'!$B$35 -> 26700 | D16: =B16*C16 -> 1548600 | E16: =B16*('02_Assumptions'!$B$36+'02_Assumptions'!$B$13+'02_Assumptions'!$B$35*'02_Assumptions'!$B$12+'02_Assumptions'!$B$14+'02_Assumptions'!$B$15+'02_Assumptions'!$B$16) -> 972544 | F16: =D16-E16 -> 576056 | G16: =B16*'02_Assumptions'!$B$17 -> 261000 | H16: =F16-G16 -> 315056 | I16: ='02_Assumptions'!$B$33 -> 420750 | J16: =H16-I16 -> -105694
A17: 年計 | B17: =SUM(B5:B16) -> 696 | C17: ='02_Assumptions'!$B$35 -> 26700 | D17: =SUM(D5:D16) -> 18583200 | E17: =SUM(E5:E16) -> 11670528 | F17: =SUM(F5:F16) -> 6912672 | G17: =SUM(G5:G16) -> 3132000 | H17: =SUM(H5:H16) -> 3780672 | I17: =SUM(I5:I16) -> 5049000 | J17: =SUM(J5:J16) -> -1268328 | K17: 完売しても年間営業赤字
A18: 注記
A19: この計画は「700個を全て売り切った」最良の消化ケース。それでも営業利益は年 −1,268,328円。
A20: 黒字化には月78個（年936個）が必要。700個では数量そのものが足りない。
A21: ★実績販売数が判明次第、B列を実績で置き換えること。

Sheet 08_Advertising
A1: 広告分析
A2: ★広告実績が未提出。媒体別の入力枠と判定基準を提示。ROASではなく「限界利益ROAS」で判断する。
A4: 日付 | B4: 媒体 | C4: Campaign | D4: Creative | E4: 広告費 | F4: Imp | G4: CPM | H4: Click | I4: CTR | J4: CPC | K4: LP View | L4: CV | M4: CVR | N4: CPA | O4: 売上 | P4: ROAS | Q4: 限界利益ROAS | R4: 注記
B5: Meta
B6: Google
B7: Amazon
B8: 楽天RPP
B9: TikTok
B10: インフルエンサー
B11: アフィリエイト
B12: SEO/オーガニック
B13: PR
A15: 判定基準（社内基準）
A16: 指標 | B16: 目標 | C16: 許容上限 | D16: 停止ライン
A17: CPA | B17: ¥4,500 | C17: ¥6,000 | D17: ¥6,000超が7日連続 → 停止
A18: 広告費率（広告費÷売上） | B18: 15% | C18: 20% | D18: 20%超が継続 → 停止
A19: 限界利益ROAS | B19: 2.0以上 | C19: 1.0 | D19: 1.0未満＝売るほど赤字。即停止
A20: ROAS（売上ベース） | B20: 参考値 | C20: — | D20: ★ROAS単独で黒字判断しない
A22: 限界利益ROAS の現在値
A23: CPA | B23: 限界利益ROAS | C23: 判定
A24: 3600 | B24: 2.7588889 | C24: 楽観
A25: 4500 | B25: 2.2071111 | C25: 目標
A26: 6000 | B26: 1.6553333 | C26: 許容上限
A27: 9932 | B27: 1 | C27: 完全赤字ライン
A28: 注記
A29: 限界利益ROAS ＝ 粗利 ÷ 広告費。1.0を割ったら、売上が伸びていても赤字。
A30: MIX粗利 9,932円 ÷ CPA4,500 = 2.21。CPA6,000なら1.66。CPA9,932で1.00＝完全赤字ライン。
A31: 広告依存率：オーガニック流入比率が未計測。広告停止で売上がゼロになる構造なら、事業価値はほぼゼロと評価する。

Sheet 09_Funnel
A1: ファネル分析
A2: ★各段階の実数が未提出。枠とボトルネック仮説を提示。責任者は必ず1名置くこと。
A4: 段階 | B4: 母数 | C4: CV数 | D4: CVR | E4: 業界目安 | F4: 改善余地 | G4: 責任者 | H4: 注記
A5: 認知（Imp）
A6: クリック | D6: =IF(B6=0,0,C6/B6) -> 0
A7: LP到達 | D7: =IF(B7=0,0,C7/B7) -> 0
A8: カート投入 | D8: =IF(B8=0,0,C8/B8) -> 0
A9: 購入・予約 | D9: =IF(B9=0,0,C9/B9) -> 0
A10: 入金完了 | D10: =IF(B10=0,0,C10/B10) -> 0
A11: レビュー投稿 | D11: =IF(B11=0,0,C11/B11) -> 0
A12: リピート | D12: =IF(B12=0,0,C12/B12) -> 0
A13: 紹介 | D13: =IF(B13=0,0,C13/B13) -> 0
A15: ボトルネック仮説（1つに絞る）
A16: 想定ボトルネック：【LP → 購入】のCVR。2〜3万円のスーツケースは「触れない不安」が最大の離脱要因。
A17: 理由：価格帯的に比較検討が長く、レビュー数・実測重量・容量比較・返品条件が意思決定を左右する。
A18: 検証方法：LPにサイズ比較動画・実測重量・返品ポリシーを追加し、A/BでCVR差分を測る。広告費を増やす前にここを潰す。
A19: ★ただしCVRの実数が未提出のため上記は仮説。まず現状CVRを出すこと。

Sheet 10_P&L
A1: 損益計算（年間・3シナリオ）
A2: 営業利益がマイナス＝売っても固定費を回収できていない。悲観から先に見る。
A4: 項目 | B4: 悲観 | C4: 標準 | D4: 楽観 | E4: 注記
A5: 年間販売数 | B5: =ROUND('02_Assumptions'!$B$43*'02_Assumptions'!$B$25,0)*12 -> 348 | C5: ='02_Assumptions'!$B$43*12 -> 696 | D5: =ROUND('02_Assumptions'!$B$43*'02_Assumptions'!$B$27,0)*12 -> 1044 | E5: 悲観=標準50% / 楽観=標準150%
A6: CPA | B6: ='02_Assumptions'!$B$17*'02_Assumptions'!$B$26 -> 6750 | C6: ='02_Assumptions'!$B$17 -> 4500 | D6: ='02_Assumptions'!$B$17*'02_Assumptions'!$B$28 -> 3600 | E6: 悲観150% / 標準=社内目標 / 楽観80%
A7: 売上高 | B7: =B5*'02_Assumptions'!$B$35 -> 9291600 | C7: =C5*'02_Assumptions'!$B$35 -> 18583200 | D7: =D5*'02_Assumptions'!$B$35 -> 27874800 | E7: 平均単価26,700円×数量
A8: 売上原価（原価+送料+手数料） | B8: =B5*('02_Assumptions'!$B$36+'02_Assumptions'!$B$13+'02_Assumptions'!$B$35*'02_Assumptions'!$B$12+'02_Assumptions'!$B$14+'02_Assumptions'!$B$15+'02_Assumptions'!$B$16) -> 5835264 | C8: =C5*('02_Assumptions'!$B$36+'02_Assumptions'!$B$13+'02_Assumptions'!$B$35*'02_Assumptions'!$B$12+'02_Assumptions'!$B$14+'02_Assumptions'!$B$15+'02_Assumptions'!$B$16) -> 11670528 | D8: =D5*('02_Assumptions'!$B$36+'02_Assumptions'!$B$13+'02_Assumptions'!$B$35*'02_Assumptions'!$B$12+'02_Assumptions'!$B$14+'02_Assumptions'!$B$15+'02_Assumptions'!$B$16) -> 17505792 | E8: ★関税・国際送料・倉庫・返品は未算入
A9: 売上総利益（粗利） | B9: =B7-B8 -> 3456336 | C9: =C7-C8 -> 6912672 | D9: =D7-D8 -> 10369008 | E9: 粗利率37.2%
A10: 広告宣伝費 | B10: =B5*B6 -> 2349000 | C10: =C5*C6 -> 3132000 | D10: =D5*D6 -> 3758400
A11: 限界利益 | B11: =B9-B10 -> 1107336 | C11: =C9-C10 -> 3780672 | D11: =D9-D10 -> 6610608 | E11: 粗利 − 広告費
A12: 固定費 | B12: ='02_Assumptions'!$B$34*12 -> 5555065.6 | C12: ='02_Assumptions'!$B$33*12 -> 5049000 | D12: ='02_Assumptions'!$B$33*12 -> 5049000 | E12: 悲観のみ実績平均を使用
A13: 営業利益 | B13: =B11-B12 -> -4447729.6 | C13: =C11-C12 -> -1268328 | D13: =D11-D12 -> 1561608 | E13: ★標準ケースでも赤字
A14: 営業利益率 | B14: =B13/B7 -> -0.47868285 | C14: =C13/C7 -> -0.068251324 | D14: =D13/D7 -> 0.056022214
A15: 注記
A16: 標準ケース（700個を12ヶ月で完売）でも営業利益 −1,268,328円。これが本審査の核心。
A17: 黒字化の条件は ①年936個以上 ②CPA3,600円以下 ③粗利率50% ④固定費月30万円以下 のいずれか。
A18: ★未算入コストを1,000円/個入れると、楽観ケースの営業利益も +1,561,608 → +517,608円まで縮む。

Sheet 11_Cash Flow
A1: キャッシュフロー・最大運転資金
A2: 利益が出ても現金が尽きれば終わる。発注→最終入金まで資金が寝る期間を日数で見る。
A4: 資金サイクル（700個ロット）
A5: 工程 | B5: 経過日数 | C5: 支出 | D5: 入金 | E5: 累計残高影響 | F5: 注記
A6: 発注・前金 | B6: 0 | C6: ='02_Assumptions'!$B$44*'02_Assumptions'!$B$29 -> 3234000 | E6: -3234000 | F6: 手元資金から流出
A7: 製造 | B7: 60 | E7: -3234000 | F7: 仮定60日
A8: 残金支払・船積 | B8: 65 | C8: ='02_Assumptions'!$B$44*(1-'02_Assumptions'!$B$29) -> 7546000 | E8: -10780000 | F8: ★ここで最大流出
A9: 海上輸送 | B9: 85 | E9: -10780000 | F9: 仮定20日
A10: 通関・国内入庫 | B10: ='02_Assumptions'!$B$30 -> 90 | E10: -10780000 | F10: 関税・通関費は未算入（要確認）
A11: 販売開始 | B11: 95 | E11: -10780000 | F11: 以降、広告費が毎月発生
A12: 初回入金 | B12: =95+'02_Assumptions'!$B$31 -> 125 | D12: ='02_Assumptions'!$B$43*'02_Assumptions'!$B$35 -> 1548600 | E12: -9231400 | F12: モール締め後
A13: 全量販売完了 | B13: 455 | E13: -9231400 | F13: 月58個ペースで12ヶ月
A14: 最終入金 | B14: 485 | E14: -9231400 | F14: 発注から約16ヶ月
A16: 最大運転資金の推定
A17: 項目 | B17: 金額 | F17: 注記
A18: 700個 仕入原価 | B18: ='02_Assumptions'!$B$44 -> 10780000 | F18: ミックス加重・現行単価。数量割引が取れれば減る
A19: 固定費 3ヶ月分 | B19: ='02_Assumptions'!$B$33*3 -> 1262250 | F19: 販売開始前〜初回入金までの空白
A20: 広告費 3ヶ月分 | B20: ='02_Assumptions'!$B$43*'02_Assumptions'!$B$17*3 -> 783000 | F20: 月58個×CPA4,500
A21: 次回支払い（既定） | B21: 1373395 | F21: マーケ396万W＋今回入荷33個405万W＋固定費等
A22: 関税・国際送料・通関 | B22: ='02_Assumptions'!$B$14*'02_Assumptions'!$B$24 -> 0 | F22: ★未算入。実額を入れること
A23: 最大運転資金 合計 | B23: =SUM(B18:B22) -> 14198645 | F23: この金額が手元にないと資金ショートする
A25: 過去9ヶ月の総支出 | B25: =37875450*'02_Assumptions'!$B$5 -> 4166299.5 | F25: 比較対象
A26: 倍率 | B26: =B25/B24 -> 3.4079751 | F26: 回収前に先出しする資金の大きさ
A27: 注記
A28: 最大運転資金 約14,198,645円。過去9ヶ月の総支出（約4,166,300円）の3.4倍を、回収前に先出しすることになる。
A29: ★手元キャッシュが未開示。これが最大運転資金を下回るなら、700個発注はその時点で不可能。
A30: 発注から最終入金まで約16ヶ月。この間ずっと資金が寝る。

Sheet 12_Inventory
A1: 在庫分析
A2: 在庫は売れ残れば現金が紙に変わる。消化月数と回転日数で危険度を測る。
A4: 項目 | B4: 悲観(月29個) | C4: 標準(月58個) | D4: 楽観(月87個) | E4: 健全値 | F4: 注記
A5: 700個の消化月数 | B5: ='02_Assumptions'!$B$24/ROUND('02_Assumptions'!$B$43*'02_Assumptions'!$B$25,0) -> 24.137931 | C5: ='02_Assumptions'!$B$24/'02_Assumptions'!$B$43 -> 12.068966 | D5: ='02_Assumptions'!$B$24/ROUND('02_Assumptions'!$B$43*'02_Assumptions'!$B$27,0) -> 8.045977 | E5: ≤6ヶ月 | F5: 12ヶ月超＝型落ちリスク
A6: 在庫回転日数 | B6: ='02_Assumptions'!$B$24/ROUND('02_Assumptions'!$B$43*'02_Assumptions'!$B$25,0)*30 -> 724.13793 | C6: ='02_Assumptions'!$B$24/'02_Assumptions'!$B$43*30 -> 362.06897 | D6: ='02_Assumptions'!$B$24/ROUND('02_Assumptions'!$B$43*'02_Assumptions'!$B$27,0)*30 -> 241.37931 | E6: 60〜90日 | F6: EC物販の健全値は60〜90日
A7: 滞留在庫（12ヶ月後） | B7: =MAX(0,'02_Assumptions'!$B$24-ROUND('02_Assumptions'!$B$43*'02_Assumptions'!$B$25,0)*12) -> 352 | C7: =MAX(0,'02_Assumptions'!$B$24-'02_Assumptions'!$B$43*12) -> 4 | D7: =MAX(0,'02_Assumptions'!$B$24-ROUND('02_Assumptions'!$B$43*'02_Assumptions'!$B$27,0)*12) -> 0 | E7: 0個 | F7: 悲観では352個が残る
A8: 滞留在庫の評価額 | B8: =MAX(0,'02_Assumptions'!$B$24-ROUND('02_Assumptions'!$B$43*'02_Assumptions'!$B$25,0)*12)*'02_Assumptions'!$B$36 -> 5420800 | C8: =MAX(0,'02_Assumptions'!$B$24-'02_Assumptions'!$B$43*12)*'02_Assumptions'!$B$36 -> 61600 | D8: =MAX(0,'02_Assumptions'!$B$24-ROUND('02_Assumptions'!$B$43*'02_Assumptions'!$B$27,0)*12)*'02_Assumptions'!$B$36 -> 0 | E8: ¥0 | F8: ★半額処分ならこの半分が損失
A9: 半額処分時の損失 | B9: =MAX(0,'02_Assumptions'!$B$24-ROUND('02_Assumptions'!$B$43*'02_Assumptions'!$B$25,0)*12)*'02_Assumptions'!$B$36*0.5 -> 2710400 | C9: =MAX(0,'02_Assumptions'!$B$24-'02_Assumptions'!$B$43*12)*'02_Assumptions'!$B$36*0.5 -> 30800 | D9: =MAX(0,'02_Assumptions'!$B$24-ROUND('02_Assumptions'!$B$43*'02_Assumptions'!$B$27,0)*12)*'02_Assumptions'!$B$36*0.5 -> 0 | E9: ¥0 | F9: 在庫リスクの実額
A10: 現行在庫33個の消化月数 | B10: =33/ROUND('02_Assumptions'!$B$43*'02_Assumptions'!$B$25,0) -> 1.137931 | C10: =33/'02_Assumptions'!$B$43 -> 0.56896552 | D10: =33/ROUND('02_Assumptions'!$B$43*'02_Assumptions'!$B$27,0) -> 0.37931034 | E10: — | F10: 今回入荷分
A12: 700個は現行入荷33個の何倍か | B12: ='02_Assumptions'!$B$24/33 -> 21.212121 | E12: 倍 | F12: ★実績データなしで21倍の在庫を持つことになる
A13: 注記
A14: ★700個は現在の入荷ペース（33個）の21倍。販売実績が未提出のまま21倍の在庫を持つのは承認できない。
A15: スーツケースは色・型番の陳腐化が早く、滞留在庫は値引き処分が前提になる。悲観ケースでは約271万円の損失。
A16: 倉庫費が未算入。700個（S/M/L混在）の保管スペースと月額費用を必ず見積もること。
A17: 推奨：一括ではなく100〜150個×複数回の分割発注。単価は上がるが在庫リスクは約1/5になる。

Sheet 13_Scenario
A1: 3シナリオ比較
A2: 悲観ケースで死なないことが投資の最低条件。
A4: 項目 | B4: 悲観 | C4: 標準 | D4: 楽観 | E4: 前提・注記
A5: 月販売数 | B5: ='10_P&L'!B5/12 -> 29 | C5: ='10_P&L'!C5/12 -> 58 | D5: ='10_P&L'!D5/12 -> 87 | E5: 標準=700個÷12ヶ月
A6: CPA | B6: ='10_P&L'!B6 -> 6750 | C6: ='10_P&L'!C6 -> 4500 | D6: ='10_P&L'!D6 -> 3600 | E6: 悲観150%/標準=目標/楽観80%
A7: 年間売上 | B7: ='10_P&L'!B7 -> 9291600 | C7: ='10_P&L'!C7 -> 18583200 | D7: ='10_P&L'!D7 -> 27874800
A8: 年間粗利 | B8: ='10_P&L'!B9 -> 3456336 | C8: ='10_P&L'!C9 -> 6912672 | D8: ='10_P&L'!D9 -> 10369008
A9: 年間広告費 | B9: ='10_P&L'!B10 -> 2349000 | C9: ='10_P&L'!C10 -> 3132000 | D9: ='10_P&L'!D10 -> 3758400
A10: 年間限界利益 | B10: ='10_P&L'!B11 -> 1107336 | C10: ='10_P&L'!C11 -> 3780672 | D10: ='10_P&L'!D11 -> 6610608
A11: 年間固定費 | B11: ='10_P&L'!B12 -> 5555065.6 | C11: ='10_P&L'!C12 -> 5049000 | D11: ='10_P&L'!D12 -> 5049000 | E11: 悲観のみ実績平均
A12: 年間営業利益 | B12: ='10_P&L'!B13 -> -4447729.6 | C12: ='10_P&L'!C13 -> -1268328 | D12: ='10_P&L'!D13 -> 1561608 | E12: ★標準でも赤字
A13: 営業利益率 | B13: ='10_P&L'!B14 -> -0.47868285 | C13: ='10_P&L'!C14 -> -0.068251324 | D13: ='10_P&L'!D14 -> 0.056022214
A14: 注記
A15: 悲観ケースの年間赤字 −4,447,730円。過去9ヶ月の総支出（417万円）を1年で吹き飛ばす規模。
A16: 楽観ケースのみ黒字（+1,561,608円）。ただし月87個＝現在の入荷ペースの2.6倍を安定して売る根拠が未提示。
A17: 投資判断の原則：標準ケースで赤字の事業に大型投資はしない。

Sheet 14_Risk
A1: リスク登録簿（24件）
A2: Score = 発生確率 × 影響度（各1〜5）。Score20以上（赤）は投資前に潰す。上位には必ず対策と責任者。
A4: No | B4: リスク | C4: 分類 | D4: 発生確率 | E4: 影響度 | F4: Score | G4: 予防策 | H4: 発生時対応 | I4: 責任者
A5: 1 | B5: 700個が売れ残り滞留在庫化する | C5: 在庫 | D5: 5 | E5: 5 | F5: =D5*E5 -> 25 | G5: 分割発注に切替／予約販売で需要を先に取る | H5: 値引き処分＋B2B卸・アウトレット放出 | I5: 北野
A6: 2 | B6: 販売実績データが無いまま投資し前提が全て外れる | C6: 市場 | D6: 5 | E6: 5 | F6: =D6*E6 -> 25 | G6: MVPで30日実測してから次の投資 | H6: Gate未達なら発注しない | I6: 北野
A7: 3 | B7: 手元キャッシュが最大運転資金1,420万円に届かない | C7: キャッシュ | D7: 4 | E7: 5 | F7: =D7*E7 -> 20 | G7: 発注前に資金繰り表を作成／分割発注で山を下げる | H7: 発注延期。借入は限界利益黒字化後 | I7: 北野
A8: 4 | B8: モール手数料が実際は10〜15%で限界利益が消える | C8: 価格 | D8: 4 | E8: 5 | F8: =D8*E8 -> 20 | G8: 各モールの実手数料を契約書で確認 | H8: 価格改定または該当モール撤退 | I8: 要任命
A9: 5 | B9: 関税・国際送料・倉庫費が未算入で採算が崩れる | C9: 物流 | D9: 4 | E9: 4 | F9: =D9*E9 -> 16 | G9: 通関業者・3PLに事前見積 | H9: 売価改定／原価交渉 | I9: 要任命
A10: 6 | B10: 競合が同型番の廉価版を投入し価格競争になる | C10: 競合 | D10: 4 | E10: 4 | F10: =D10*E10 -> 16 | G10: 意匠登録／レビュー資産の先行構築 | H10: 価格では追わずバンドル・保証で差別化 | I10: 北野
A11: 7 | B11: 固定費（月382万W）が売上に先行して膨らむ | C11: キャッシュ | D11: 4 | E11: 4 | F11: =D11*E11 -> 16 | G11: 黒字化まで固定費を増やさない | H11: 人件費・家賃の見直し | I11: 北野
A12: 8 | B12: 広告依存度が高く広告停止で売上がゼロになる | C12: 広告 | D12: 4 | E12: 4 | F12: =D12*E12 -> 16 | G12: オーガニック比率を計測・KPI化 | H12: SEO/SNSへ段階的にシフト | I12: 要任命
A13: 9 | B13: サンクコスト（既払マーケ費・既存在庫）で判断が歪む | C13: 組織 | D13: 4 | E13: 4 | F13: =D13*E13 -> 16 | G13: Kill Criteriaを事前に文書化 | H13: 既払費用は判断材料から除外 | I13: 北野
A14: 10 | B14: CPAが許容上限6,000円を超え広告が回らない | C14: 広告 | D14: 3 | E14: 5 | F14: =D14*E14 -> 15 | G14: 小ロットで実CPAを測定してから増資 | H14: 広告停止→オーガニック検証に切替 | I14: 要任命
A15: 11 | B15: 為替が円安に振れ原価が上昇する | C15: 為替 | D15: 3 | E15: 4 | F15: =D15*E15 -> 12 | G15: 為替予約／複数回に分けて発注 | H15: 売価改定 | I15: 北野
A16: 12 | B16: 返品率が想定を超える（大型商品は返送料が高い） | C16: 品質 | D16: 3 | E16: 4 | F16: =D16*E16 -> 12 | G16: 返品ポリシー明記／サイズ比較コンテンツ | H16: 返品理由を分類し商品改善 | I16: 要任命
... A28: 24 | B28: 韓国法人→日本販売の税務・移転価格の指摘 | C28: 税務 | D28: 2 | E28: 4 | F28: =D28*E28 -> 8 | G28: 税理士に事前確認 | H28: 修正申告 | I28: 税理士
A29: 注記
A30: Score20以上（赤）は投資前に潰すべきリスク。うち3件は「データが無いこと」そのものが原因＝Gate0で解消できる。
A31: 「要任命」の責任者は空欄のままにしない。1名を必ず指名すること。

Sheet 15_MVP
A1: MVP設計と投資ゲート
A2: 大規模投資の前に最小費用で「需要・価格・CVR・CPA」を実測する。Gate未達なら次の金を出さない。
A4: MVP（最小検証）
A5: No | B5: 検証内容 | C5: 費用 | D5: 期間 | E5: 方法 | F5: 責任者
A6: 1 | B6: L の予約販売で実需を測る | C6: ¥0 | D6: 14日 | E6: 在庫ゼロのまま予約ページを公開。予約数＝実需。キャッシュを使わない最強の検証 | F6: 北野
A7: 2 | B7: モール実手数料の確認 | C7: ¥0 | D7: 3日 | E7: 楽天・Amazon・自社ECの契約書と精算レポートから実負担率を算出 | F7: 北野
A8: 3 | B8: 関税・国際送料・倉庫の実見積 | C8: ¥0 | D8: 7日 | E8: 通関業者・3PLに700個ベースで見積依頼 | F8: 要任命
A9: 4 | B9: 過去の販売実績・CPA・CVRを集計 | C9: ¥0 | D9: 5日 | E9: キントーン＋各媒体レポートからSKU別・媒体別の月次実績を出す | F9: 要任命
A10: 5 | B10: 700個の仕入単価を交渉 | C10: ¥0 | D10: 14日 | E10: 数量別単価の書面回答を取る。▲20%で損益分岐78→50個 | F10: 北野
A11: 6 | B11: 価格弾力性テスト | C11: ¥0 | D11: 14日 | E11: S を21,900／24,900の2価格でA/B。CVR差分を見る | F11: 要任命
A12: 7 | B12: 広告テスト | C12: ¥150,000 | D12: 30日 | E12: Meta+Google 日額5,000円。CV数・CPA・CVRを実測 | F12: 要任命
A14: 投資ゲート（条件を全て満たすまで次に進まない）
A15: Gate | B15: 投資額 | C15: 突破条件 | D15: 期限 | E15: 未達の場合 | F15: 責任者
A16: Gate0 | B16: ¥0 | C16: 実手数料・関税/倉庫費・手元キャッシュ・700個数量割引単価・過去実績 の5点が全て数値で確定 | D16: 9/18 | E16: 700個発注を白紙に戻す | F16: 北野
A17: Gate1 | B17: ¥150,000 | C17: 30日で CV≥10件 かつ CPA≤¥6,000 かつ CVR≥0.8% | D17: 10/11 | E17: 広告停止。商品・LPを作り直す | F17: 要任命
A18: Gate2 | B18: ¥500,000 | C18: 60日で CPA≤¥4,500 かつ 月販≥30個 かつ 返品率≤5% | D18: 11/10 | E18: Gate1に戻す。追加投資しない | F18: 要任命
A19: Gate3 | B19: ¥1,000,000 | C19: 90日で 月販≥58個 かつ 限界利益が月次で黒字 | D19: 12/10 | E19: 100個のみ追加発注に縮小 | F19: 北野
A20: Gate4 | B20: ¥2,200,000 | C20: 月販≥78個（損益分岐超）を2ヶ月連続 | D20: 2027/02 | E20: 分割発注を継続。700個は見送り | F20: 北野
A21: Gate5 | B21: 700個 本格発注 | C21: 月販≥100個を3ヶ月連続 かつ 手元キャッシュ≥¥15,000,000 | D21: 条件達成時 | E21: 実行しない | F21: 北野
A23: Kill Criteria（撤退基準・事前確定）
A24: No | B24: 基準 | C24: 判定タイミング
A25: 1 | B25: 30日CPAが¥6,000を超える | C25: Gate1
A26: 2 | B26: 60日CVRが0.8%未満 | C26: Gate2
A27: 3 | B27: 返品率が5%を超える | C27: Gate2
A28: 4 | B28: 広告費50万円投下後も月販30個未満 | C28: Gate2
A29: 5 | B29: 限界利益率が15%未満 | C29: 月次
A30: 6 | B30: 在庫回転が120日を超える | C30: 月次
A31: 7 | B31: 営業赤字が2ヶ月連続 | C31: 月次
A32: 8 | B32: 手元キャッシュが固定費3ヶ月分を下回る | C32: 月次 | F32: 即時停止
A33: 注記
A34: Gate0は費用ゼロ。今日から着手できる。ここを飛ばして発注するのが最悪の選択。
A35: ★現時点の推奨投資上限は Gate4 までの累計 ¥2,200,000（小ロット150個相当）。700個への一括投資は承認しない。
A36: Kill Criteria は経営者の感情で動かさない。事前に文書化し、担当者と共有すること。

Sheet 16_KPI Dashboard
A1: KPIダッシュボード
A2: Daily/Weekly/Monthly を分ける。黄色＝実績入力欄。異常値検知ルールは下部。
A4: 【Daily】
B5: 指標 | C5: 目標 | D5: 許容ライン | E5: 実績 | F5: 判定 | G5: 警告条件・対応
B6: 売上 | C6: — | D6: — | G6: 前日比 −20%で警告
B7: 販売数 | C7: — | D7: — | G7: 前日比 −20%で警告
B8: 広告費 | C8: 日額上限を設定 | D8: — | G8: 上限超過で自動停止
B9: CPA | C9: ¥4,500 | D9: ¥6,000 | G9: +20%で警告
B10: 限界利益ROAS | C10: 2.0以上 | D10: 1.0 | G10: 1.0割れで即停止
B11: CVR | C11: — | D11: — | G11: −20%で警告
B12: 在庫数 | C12: — | D12: — | G12: SKU別。欠品/滞留の両方を見る
A14: 【Weekly】
B15: 指標 | C15: 目標 | D15: 許容ライン | E15: 実績 | F15: 判定 | G15: 警告条件・対応
B16: 粗利率 | C16: 37.2%以上 | D16: — | G16: 低下で警告
B17: 限界利益率 | C17: 20.3%以上 | D17: 15% | G17: 15%割れでKill判定
B18: 広告費率 | C18: 15% | D18: 20% | G18: 20%超で警告
B19: SKU別売上 | C19: — | D19: — | G19: 死にSKUの特定
B20: チャネル別売上 | C20: — | D20: — | G20: 広告依存率を必ず見る
B21: 返品率 | C21: ≤3% | D21: 5% | G21: +30%で警告
B22: レビュー件数/評価 | C22: — | D22: ≥4.0 | G22: 低評価は即対応
B23: 在庫回転日数 | C23: ≤90日 | D23: 120日 | G23: 超過で値引き検討
A25: 【Monthly】
B26: 指標 | C26: 目標 | D26: 許容ライン | E26: 実績 | F26: 判定 | G26: 警告条件・対応
B27: 営業利益 | C27: 黒字 | D27: — | G27: 2ヶ月連続赤字でKill判定
B28: キャッシュ残高 | C28: — | D28: 固定費3ヶ月分 | G28: 下回ったら即時停止
B29: LTV | C29: — | D29: — | G29: 低頻度商材のため初回≒LTV
B30: CAC | C30: ¥4,500 | D30: ¥6,000
B31: LTV/CAC（限界利益ベース） | C31: ≥2.0 | D31: 1.0 | G31: 現状1.2は危険水準
B32: 固定費 | C32: ≤¥420,750 | D32: — | G32: 黒字化まで増やさない
B33: 人件費率 | C33: — | D33: — | G33: 売上比で管理
B34: 在庫評価額 | C34: — | D34: — | G34: 滞留分は評価減を計上
A36: 異常値検知ルール（原因候補 → 確認データ → 対策）
A37: CPA +20%以上 → 入札競合増／クリエイティブ疲弊／LP不調 → 媒体別CPA・CTR・CVR → クリエイティブ差替、入札上限設定
A38: CVR −20%以上 → LP改変／欠品／価格改定／競合値下げ → LP解析・在庫・競合価格 → 直前の変更を戻す
A39: 売上 −20%以上 → 広告停止／季節要因／アカウント制限 → 媒体アカウント状態・前年同月 → 原因特定まで広告増額しない
A40: 返品率 +30%以上 → 品質不良ロット／サイズ誤認 → 返品理由の分類 → 該当ロット出荷停止
A41: 在庫回転 悪化 → 過剰発注／SKUミスマッチ → SKU別回転日数 → 追加発注停止、値引き計画
A42: 粗利率 低下 → 値引き／手数料増／為替 → 06_Unit Economics を再計算 → 値引き停止または売価改定
A43: 広告費率 上昇 → CPA悪化／客単価低下 → 媒体別・SKU別の広告費率 → 20%超の媒体を停止

Sheet 17_Action Plan
A1: 30日アクションプラン（RACI・ICE）
A2: R=実行 A=最終責任／ICE=Impact×Confidence×Ease（各1-10）。「みんなでやる」は禁止。責任者は必ず1名。
A4: 優 | B4: タスク | C4: 目的 | D4: R(実行) | E4: A(責任) | F4: 開始 | G4: 期限 | H4: KPI/完了条件 | I4: 状態 | J4: 次回アクション | K4: I | L4: C | M4: E | N4: ICE
A5: 1 | B5: 700個の発注を一旦保留する | C5: 最大リスクの回避 | D5: 北野 | E5: 北野 | F5: 9/11 | G5: 9/11 | H5: サプライヤーへ保留連絡済み | I5: 未着手 | J5: Gate4まで凍結 | K5: 10 | L5: 10 | M5: 10 | N5: =K5*L5*M5 -> 1000
A6: 2 | B6: モール実手数料を契約書で確定 | C6: 4%前提が崩れないか確認 | D6: 北野 | E6: 北野 | F6: 9/11 | G6: 9/15 | H6: 3チャネルの実負担率を数値化 | I6: 未着手 | J6: 02/06シート更新 | K6: 10 | L6: 9 | M6: 9 | N6: =K6*L6*M6 -> 810
A7: 3 | B7: Kill Criteria を文書化し全員共有 | C7: 感情での継続を防ぐ | D7: 北野 | E7: 北野 | F7: 9/11 | G7: 9/13 | H7: 署名付きの撤退基準文書 | I7: 未着手 | J7: 月次レビュー | K7: 8 | L7: 10 | M7: 10 | N7: =K7*L7*M7 -> 800
A8: 4 | B8: 手元キャッシュと資金繰り表を作る | C8: 1,420万円を出せるか判定 | D8: 北野 | E8: 北野 | F8: 9/11 | G8: 9/15 | H8: 月次資金繰り表12ヶ月分 | I8: 未着手 | J8: 11シート更新 | K8: 10 | L8: 10 | M8: 8 | N8: =K8*L8*M8 -> 800
A9: 5 | B9: 関税・国際送料・倉庫費の実見積 | C9: 未算入コストを潰す | D9: 要任命 | E9: 北野 | F9: 9/11 | G9: 9/18 | H9: 700個ベースの円/個が確定 | I9: 未着手 | J9: 02シート更新 | K9: 10 | L9: 8 | M9: 8 | N9: =K9*L9*M9 -> 640
A10: 6 | B10: 過去の販売実績・CPA・CVRを集計 | C10: 全前提の検証 | D10: 要任命 | E10: 北野 | F10: 9/11 | G10: 9/16 | H10: SKU別・媒体別の月次実績 | I10: 未着手 | J10: 02/07/08シート更新 | K10: 10 | L10: 9 | M10: 7 | N10: =K10*L10*M10 -> 630
A11: 7 | B11: L の予約販売ページを公開 | C11: 在庫ゼロで実需を測る | D11: 要任命 | E11: 北野 | F11: 9/11 | G11: 9/18 | H11: 14日間の予約件数 | I11: 未着手 | J11: Gate1判定 | K11: 9 | L11: 8 | M11: 8 | N11: =K11*L11*M11 -> 576
A12: 8 | B12: 分割発注（100〜150個）の条件を取る | C12: 在庫リスクを1/5に | D12: 北野 | E12: 北野 | F12: 9/11 | G12: 9/25 | H12: 分割時の単価・最低ロット | I12: 未着手 | J12: Gate3判定 | K12: 9 | L12: 8 | M12: 7 | N12: =K12*L12*M12 -> 504
A13: 9 | B13: KPIダッシュボードを日次運用に乗せる | C13: 異常の早期検知 | D13: 要任命 | E13: 北野 | F13: 9/15 | G13: 9/30 | H13: Daily7指標が毎朝見える | I13: 未着手 | J13: 週次レビュー | K13: 8 | L13: 9 | M13: 7 | N13: =K13*L13*M13 -> 504
A14: 10 | B14: 広告テスト（日額5,000円×30日） | C14: 実CPAの取得 | D14: 要任命 | E14: 北野 | F14: 9/18 | G14: 10/18 | H14: CV≥10件 CPA≤6,000 | I14: 未着手 | J14: Gate1判定 | K14: 9 | L14: 7 | M14: 7 | N14: =K14*L14*M14 -> 441
A15: 11 | B15: 700個の仕入単価を交渉 | C15: ▲20%で損益分岐78→50個 | D15: 北野 | E15: 北野 | F15: 9/11 | G15: 9/25 | H15: 数量別単価の書面回答 | I15: 未着手 | J15: 再審査 | K15: 10 | L15: 7 | M15: 6 | N15: =K15*L15*M15 -> 420
A16: 12 | B16: 返品ポリシーとサイズ比較コンテンツ整備 | C16: CVR改善と返品抑制 | D16: 要任命 | E16: 北野 | F16: 9/18 | G16: 10/05 | H16: LPに実測重量・容量比較を掲載 | I16: 未着手 | J16: CVR計測 | K16: 7 | L16: 7 | M16: 8 | N16: =K16*L16*M16 -> 392
A18: 今はやらないこと（重要だが今ではない）
A19: 1. 700個の一括発注 — Gate4を突破するまで凍結。サンクコスト（既払マーケ費・既存在庫）は判断材料にしない。
A20: 2. 人の増員 — 固定費は黒字化まで増やさない。「人を増やせば解決」は現時点で根拠がない。
A21: 3. 新チャネル・新SKUの追加 — 既存SKUのCPA・CVRが成立していない段階で広げない。
A22: 4. 大型の広告増額 — Gate1/2の実測CPAが出るまで日額5,000円を超えない。
A24: 確認日
A25: 9/18（Gate0判定）／10/11（Gate1判定）／11/10（Gate2判定）／12/10（Gate3判定）／毎週月曜 KPIレビュー

Sheet 18_Premortem & Score
A1: プレモーテム・成功要因・最終採点
A2: 「12ヶ月後に失敗した」と仮定して理由を先に出す。次に「想定以上に成功した」要因を再現条件として抽出する。
A4: プレモーテム：12ヶ月後、この事業は失敗した。その理由15個
A5: No | B5: 失敗理由 | C5: 分類 | D5: 対応
A6: 1 | B6: 700個の在庫が捌けず、半額処分で約271万円の損失を出した | C6: 今防げる | D6: 分割発注に切替／予約販売で需要を先に測る
A7: 2 | B7: CPAが6,000円を超え続け、広告を止めたら売上がほぼゼロになった | C7: 今防げる | D7: 小ロットで実CPAを測ってから増資
A8: 3 | B8: モール手数料が実は12%で、限界利益が想定の6割しかなかった | C8: 今防げる | D8: 契約書で実負担率を確定（Gate0）
A9: 4 | B9: 関税・国際送料・倉庫費が1個1,500円かかり、損益分岐が108個/月に跳ねた | C9: 今防げる | D9: 通関業者・3PLに事前見積（Gate0）
A10: 5 | B10: 仕入代金の支払いで資金が尽き、広告を打てなくなった | C10: 今防げる | D10: 資金繰り表で最大運転資金を先に確定
A11: 6 | B11: 月58個すら売れず、固定費だけが毎月42万円流出し続けた | C11: 今防げる | D11: Gate方式で段階投資。未達なら次を出さない
A12: 7 | B12: 担当者が退職し、運用が経営者に全部戻ってきた | C12: 今防げる | D12: SOP化・責任者の明文化（17_Action Plan）
A13: 8 | B13: L の需要が想定より小さく、L在庫だけが丸ごと残った | C13: 今防げる | D13: 予約販売で実需確認してから発注
A14: 9 | B14: 季節性を読み違え、閑散期に在庫が積み上がった | C14: 今防げる | D14: 需要の山谷を月次で分解してから発注量を決める
A15: 10 | B15: サンクコストに引きずられ、赤字なのに撤退できなかった | C15: 今防げる | D15: Kill Criteriaを事前に文書化・署名
A16: 11 | B16: 競合が同型番の廉価版を出し、値下げ競争で粗利が消えた | C16: 開始後に監視 | D16: 意匠登録・レビュー資産・バンドルで防御
A17: 12 | B17: レビューが集まらずCVRが上がらないまま広告費だけ溶けた | C17: 開始後に監視 | D17: 初期購入者フォロー設計をGate1で組む
... A20: 15 | B20: スーツケース市場そのものが縮小し、何をしても数量が出なかった | C20: 防げない | D20: 早期に撤退できる在庫水準を維持する
A22: 逆に想定以上に成功したとしたら：再現可能な成功要因10個
A23: No | B23: 成功要因 | C23: 再現性 | D23: 必要条件
A24: 1 | B24: 700個発注で仕入単価が▲20%下がり、限界利益が8,512円になった | C24: 高 | D24: 数量割引の書面確約
A25: 2 | B25: L の予約販売が想定を超え、在庫を持つ前に需要が確定した | C25: 高 | D25: 予約ページの公開と14日の計測
A26: 3 | B26: 固定費を月30万円以下に抑えたまま数量を伸ばした | C26: 高 | D26: 黒字化まで増員しない規律
A27: 4 | B27: 分割発注で在庫回転90日を維持し、資金が寝なかった | C27: 高 | D27: 分割発注の条件取得
A28: 5 | B28: Kill Criteriaを守り、ダメなSKUを早期に切った | C28: 高 | D28: 撤退基準の文書化と実行
A29: 6 | B29: レビュー200件超が積み上がり、自然流入で売れる状態になった | C29: 中 | D29: 初期購入者フォローの仕組み
A30: 7 | B30: CPAが3,600円に下がり、月87個で黒字化した | C30: 中 | D30: クリエイティブの継続改善とLP最適化
A31: 8 | B31: 機内持込サイズなど明確なニッチで一位を取った | C31: 中 | D31: SKUを絞る意思決定
A32: 9 | B32: 自社EC比率を上げ、モール手数料を4%に抑え続けられた | C32: 中 | D32: 自社ECへの送客導線
A33: 10 | B33: 返品率3%以下を維持し、限界利益が計画通り残った | C33: 中 | D33: サイズ比較コンテンツと品質検査
A35: A｜最終投資審査 採点（12項目）
B36: 評価項目 | C36: 点数 /100 | D36: 評価理由
B37: 市場性 | C37: 55 | D37: 市場は存在するが成熟・レッドオーシャン。TAM/SAM/SOMの実データ未提出
B38: 顧客課題 | C38: 45 | D38: PainkillerではなくVitamin。買替サイクル5〜10年で緊急性が低く先送りされやすい
B39: 商品力 | C39: 50 | D39: 機能・品質の差別化情報が未提出。最も競争が激しい2〜3万円帯
B40: 競争優位性 | C40: 30 | D40: USP・意匠・レビュー資産のいずれも未確認。コピーされやすい構造
B41: 粗利構造 | C41: 55 | D41: 粗利率37.2%。EC物販の健全値50%に届かない。未算入コストでさらに低下
B42: ユニットエコノミクス | C42: 35 | D42: 限界利益5,432円・率20.3%。限界利益ベースのLTV/CAC 1.2倍は危険水準
B43: 広告再現性 | C43: 20 | D43: CPA・CVR・ROASの実績が一切ない。再現性が評価できない＝投資できない
B44: オペレーション | C44: 40 | D44: 700個の保管・在庫回転・3PL計画が未提出。回転362日は不健全
B45: 組織 | C45: 35 | D45: 責任者未指名の業務が多数。経営者依存。給与300万W1名前提の体制
...
