Workbook

Sheet 01_Executive Summary
A1: LIBETEE KOREA ｜ スーツケース800個 大量入荷 投資審査
A2: 対象: 今後入荷予定800個への投資判断 ／ 審査日 2026-09-16 ／ A=投資委員会・B=経営者モード ／ 数値は 02_Assumptions と連動
A4: 【結論】
A5: 1. ★これは不足データを仮値で埋めた「叩き」です。仮置きした28項目は 24_仮置き一覧 にまとめてあります。影響度Aの5項目を実数に差し替えると結論が変わりえます。
A6: 2. 仮値ベースでも、悲観 −5,154,410円／標準 −2,450,472円／楽観 −90,600円と、3シナリオすべてが年間赤字。楽観（月100個・CPA3,600円）でようやく損益トントンです。
A7: 3. 損益分岐は月131個＝年1,572個。800個／年では数量が約半分しかありません。反転条件は「CVRを1%に上げる」か「通関費・仕入単価をさらに下げる」の2つです。
A9: 【投資判断】
A10: 項目 | B10: 判定・数値 | E10: 根拠
A11: 投資判断（800個一括） | B11: 条件付きHOLD | E11: 仮値ベースで楽観ケースがほぼトントン。24_仮置き一覧の影響度A5件を確定させてから再審査
A12: 総合スコア | B12: 33.8 / 100 | E12: 18_Premortem & Score の12項目評価（仮値ベース）
A13: 損益分岐売上（月） | B13: ='02_Assumptions'!$B$69 -> 3497700 | E13: 損益分岐数量×平均単価
A14: 損益分岐販売数（月） | B14: ='02_Assumptions'!$B$67 -> 131 | E14: 固定費 ÷ 平均限界利益
A15: 損益分岐販売数（年） | B15: ='02_Assumptions'!$B$68 -> 1572 | E15: 800個／年では約半分
A16: MIX 粗利/個 | B16: ='02_Assumptions'!$B$61 -> 7732 | E16: 通関費1,000円・返品400円・ポイント800円を算入後
A17: MIX 限界利益/個 | B17: ='02_Assumptions'!$B$63 -> 3232 | E17: @目標CPA4,500円
A18: 限界利益ベース LTV/CAC | B18: 0.72 倍 | E18: 3,232円 ÷ CPA4,500円。1を下回る＝広告費を回収できていない
A19: 実績CVR（9/8-9/10） | B19: 0.0% | E19: ネイバー訪問1,207件・新規購入0件
A20: 800個 仕入原価 | B20: ='02_Assumptions'!$B$71 -> 12320000 | E20: 仮ミックス S40:M40:L20
A21: 最大運転資金 | B21: ¥16,660,145 | E21: 仕入＋固定費3ヶ月＋広告3ヶ月＋次回支払い＋通関
A22: 手元キャッシュ（仮） | B22: ¥5,000,000 | E22: ★完全な仮値。実額との差が発注可否を決める
A24: 【最大の勝ち筋】
A25: 1. CVRの改善。訪問1,207件・購入0件を1.0%にできれば、同じ広告費で月12個売れる。在庫を1個も増やさずに売上が立つ、最も費用対効果の高い打ち手。
A26: 2. 通関費のさらなる低減。800個で1,000円/個（仮）まで下がる想定だが、通関士見積で500円まで下がれば限界利益は3,232→3,732円、損益分岐は131→113個/月。
A27: 3. 仕入単価の数量割引。▲20%取れれば限界利益は3,232→6,312円、損益分岐は131→67個/月まで改善し、800個で損益分岐に到達する。
A29: 【最大のリスク】
A30: 1. 売れない在庫の積み増し。CVR 0.0%の状態で800個を入れると、滞留在庫の評価額は最大1,232万円。
A31: 2. キャッシュ枯渇。最大運転資金1,666万円に対し、手元キャッシュ（仮500万円）が大幅に不足。実額の確認が最優先。
A32: 3. 手数料前提の崩壊。ご指定の4%に対し、チャネル加重平均の推定は11.4%（25_チャネル別手数料）。実態がそちらなら限界利益は3,232→1,257円。
A34: この資料の性質
A35: ★このシートは「仮値で埋めた叩き」です。24_仮置き一覧 に仮置き28項目と差し替え先をまとめています。
A36: 実績データ：支出実績2025.12-2026.08／原価S10万W・M15万W／売価S21,900・M27,900円／9/10通関実費1,045,911W／9/8-9/10販売実績。
A37: 02_Assumptions の黄色セルを実数に書き換えると、全25シートが自動で再計算されます。

Sheet 02_Assumptions
A1: 前提条件（Assumptions）— 全シートはここを参照
A2: 確度: 実績=提出済みの実データ ／ 仮=叩き用に置いた値（24_仮置き一覧に全件リスト）／ 指定=ご指定値。黄色セル＝差し替え対象
A4: 項目 | B4: 値 | C4: 単位 | D4: 確度 | E4: 根拠・置き方／差し替え先
A5: 為替レート | B5: 0.11 | C5: 円/ウォン | D5: 仮 | E5: 1円≒9.09ウォン。実レートで要更新
A6: 売価 S | B6: 21900 | C6: 円 | D6: 指定 | E6: ご指定
A7: 売価 M | B7: 27900 | C7: 円 | D7: 指定 | E7: ご指定
A8: 売価 L | B8: 33900 | C8: 円 | D8: 仮 | E8: S→Mの刻み+6,000円から外挿
A9: 仕入原価 S | B9: 100000 | C9: ウォン | D9: 実績 | E9: スーツケース_仕入状況
A10: 仕入原価 M | B10: 150000 | C10: ウォン | D10: 実績 | E10: スーツケース_仕入状況
A11: 仕入原価 L | B11: 200000 | C11: ウォン | D11: 仮 | E11: S→Mの刻み+50,000Wから外挿
A12: モール/決済手数料率 | B12: 0.04 | C12: — | D12: 指定 | E12: ご指定4%。チャネル実態は25_チャネル別手数料 参照（推定11.4%）
A13: 送料（自社負担） | B13: 300 | C13: 円/個 | D13: 指定 | E13: ご指定
A14: 通関費/個（800個ロット） | B14: 1000 | C14: 円/個 | D14: 仮 | E14: 23_800個通関費試算の積み上げ。33個便実績2,919円の34%
A15: 通関費/個（33個便実績） | B15: 2919 | C15: 円/個 | D15: 実績 | E15: LJ関税事務所 9/10請求 875,675W(VAT除)÷33個×0.11。現在庫22個はこの原価
A16: 返品引当 | B16: 400 | C16: 円/個 | D16: 仮 | E16: 返品率5% × 1件あたり損失8,000円（往復送料+検品+価値毀損）
... A55: 12ヶ月内リピート率 | B55: 0.03 | C55: — | D55: 仮 | E55: 買替サイクル7年。2個目・付属品購入を含む
A56: 派生値（自動計算）
A57: 固定費（予想）円/月 | B57: ='02_Assumptions'!$B$23*'02_Assumptions'!$B$5 -> 420750 | D57: 算出 | E57: ウォン→円換算
A58: 固定費（実績平均）円/月 | B58: ='02_Assumptions'!$B$24*'02_Assumptions'!$B$5 -> 462922.13 | D58: 算出 | E58: 悲観ケースで使用
A59: MIX 平均売価 | B59: ='02_Assumptions'!$B$25*'02_Assumptions'!$B$6+'02_Assumptions'!$B$26*'02_Assumptions'!$B$7+'02_Assumptions'!$B$27*'02_Assumptions'!$B$8 -> 26700 | D59: 算出 | E59: ミックス加重平均
A60: MIX 平均原価（円） | B60: =('02_Assumptions'!$B$25*'02_Assumptions'!$B$9+'02_Assumptions'!$B$26*'02_Assumptions'!$B$10+'02_Assumptions'!$B$27*'02_Assumptions'!$B$11)*'02_Assumptions'!$B$5 -> 15400 | D60: 算出
A61: MIX 粗利/個（800個ロット） | B61: =$B$59-$B$59*'02_Assumptions'!$B$12-'02_Assumptions'!$B$13-$B$60-'02_Assumptions'!$B$14-'02_Assumptions'!$B$16-'02_Assumptions'!$B$17 -> 7732 | D61: 算出 | E61: 売価−手数料−送料−原価−通関−返品−ポイント
A62: MIX 粗利/個（現在庫22個） | B62: =$B$59-$B$59*'02_Assumptions'!$B$12-'02_Assumptions'!$B$13-$B$60-'02_Assumptions'!$B$15-'02_Assumptions'!$B$16-'02_Assumptions'!$B$17 -> 5813 | D62: 算出 | E62: 通関費は33個便実績を使用
A63: MIX 限界利益/個（@目標CPA） | B63: =$B$61-'02_Assumptions'!$B$18 -> 3232 | D63: 算出 | E63: 800個ロット前提
A64: MIX 限界利益/個（現在庫・@目標CPA） | B64: =$B$62-'02_Assumptions'!$B$18 -> 1313 | D64: 算出 | E64: 21_補填判断で使用
A65: MIX 限界利益/個（@実態推定CPA） | B65: =$B$61-'02_Assumptions'!$B$20 -> 732 | D65: 算出 | E65: ★CPA7,000円のケース
A66: MIX 限界利益率 | B66: =$B$63/$B$59 -> 0.12104869 | D66: 算出
A67: 損益分岐 販売数/月 | B67: =ROUNDUP($B$57/$B$63,0) -> 131 | D67: 算出 | E67: 固定費÷限界利益
A68: 損益分岐 販売数/年 | B68: =$B$67*12 -> 1572 | D68: 算出
A69: 損益分岐 売上/月 | B69: =$B$67*$B$59 -> 3497700 | D69: 算出
A70: 標準ケース 月販売数 | B70: =ROUND('02_Assumptions'!$B$28/12,0) -> 67 | D70: 算出 | E70: 800個を12ヶ月で消化する前提
A71: 800個 仕入原価（円） | B71: =('02_Assumptions'!$B$25*'02_Assumptions'!$B$9+'02_Assumptions'!$B$26*'02_Assumptions'!$B$10+'02_Assumptions'!$B$27*'02_Assumptions'!$B$11)*'02_Assumptions'!$B$28*'02_Assumptions'!$B$5 -> 12320000 | D71: 算出 | E71: ミックス加重
A72: MIX 平均容積 | B72: ='02_Assumptions'!$B$25*'02_Assumptions'!$B$49+'02_Assumptions'!$B$26*'02_Assumptions'!$B$50+'02_Assumptions'!$B$27*'02_Assumptions'!$B$51 -> 0.0734 | D72: 算出 | E72: CBM/個
A73: 800個の総容積 | B73: =$B$72*'02_Assumptions'!$B$28 -> 58.72 | D73: 算出 | E73: CBM。40ftHC(67CBM)1本で収まる
A74: 1CBMあたり海上運賃 | B74: ='02_Assumptions'!$B$52/'02_Assumptions'!$B$53 -> 29850.746 | D74: 算出 | E74: ウォン。空きスペース損失の算定に使用
A75: 注記
A76: 確度「仮」（黄色）は叩き用に置いた値です。24_仮置き一覧に全件と差し替え先をまとめてあります。
A77: 青字＝入力値、黒太字＝自動計算。黄色セルを実数に書き換えれば全シートが連動して再計算されます。
A78: ★手元キャッシュ（仮500万円）と★想定CVR（仮1.0%・実績0.0%）の2つが、判断を最も大きく動かします。

Sheet 24_仮置き一覧
A1: 仮置きした値の一覧（差し替えリスト）
A2: 叩き作成のために置いた仮値です。影響度A＝判断が変わる／B＝金額が動く／C＝軽微。Aから順に実数へ差し替えてください。
A4: No | B4: 項目 | C4: 仮値 | D4: 影響度 | E4: どこで確認できるか | F4: 置き方の根拠
A5: 1 | B5: 手元キャッシュ | C5: ¥5,000,000 | D5: A | E5: 通帳・会計ソフトの残高 | F5: ★完全な仮。発注可否の判定に直結
A6: 2 | B6: 想定CVR | C6: 1.0% | D6: A | E6: ネイバー/クーパン管理画面の転換率（広告稼働期間） | F6: EC物販の標準水準。実績は0.0%
A7: 3 | B7: 通関費/個（800個ロット） | C7: ¥1,000 | D7: A | E7: 通関士から出た800個見積 | F7: 23_800個通関費試算の積み上げ（917円）を丸め
A8: 4 | B8: 実態推定CPA | C8: ¥7,000 | D8: A | E8: Meta/Google/ネイバーGFA の管理画面 | F8: CPC60円÷(LP到達90%×CVR1.0%)
A9: 5 | B9: モール/決済手数料率 | C9: 4%（ご指定） | D9: A | E9: 各モールの契約書・精算レポート | F9: ご指定値。25_チャネル別手数料の推定は11.4%
A10: 6 | B10: SKUミックス S:M:L | C10: 40:40:20 | D10: B | E10: 800個の発注書・PIのSKU内訳 | F10: 未指定のため均等寄りで仮置き
A11: 7 | B11: L 売価 | C11: ¥33,900 | D11: B | E11: 価格決定（未確定） | F11: S→Mの刻み+6,000円から外挿
A12: 8 | B12: L 仕入原価 | C12: 200,000W | D12: B | E12: サプライヤーの見積・PI | F12: S→Mの刻み+50,000Wから外挿
A13: 9 | B13: 返品引当 | C13: ¥400/個 | D13: B | E13: ネイバー/クーパンの返品実績 | F13: 返品率5%×1件損失8,000円
A14: 10 | B14: ポイント/クーポン負担 | C14: ¥800/個 | D14: B | E14: 各モールの精算明細 | F14: 売価の3%
A15: 11 | B15: 為替レート | C15: 0.11円/W | D15: B | E15: 当日レート | F15: 1円≒9.09ウォン
A16: 12 | B16: CPC | C16: ¥60 | D16: B | E16: 各媒体の管理画面 | F16: 韓国市場の想定水準
... A32: 28 | B32: ファネル各段階 | C32: 09_Funnel参照 | D32: B | E32: 各媒体+モールの管理画面 | F32: 業界ベンチマークで仮置き
A33: 注記
A34: 影響度A（赤）は5件。この5件が揃えば投資判断の確度が大きく上がります。
A35: 影響度B（橙）は金額が動く項目、Cは全体への影響が軽微な項目です。
A36: 02_Assumptions の黄色セルを書き換えると、全シートが自動で再計算されます。

Sheet 19_通関費用実績
A1: 通関費用 実績（LJ関税事務所 I26-100263M）
A2: B/L NGTL2161196 ／ ITEM SUITCASE (TRAVEL LUGGAGE) ／ 9月10日 ／ 対象33個 ／ 全項目を検算済み（合計一致）
A4: 区分 | B4: 勘定科目 | C4: 供給価額(W) | D4: 付加価値税(W) | E4: 合計(W) | F4: 1個あたり(W) | G4: 費用の性質
A5: 運賃 | B5: 運賃 | C5: 434215 | D5: 18146 | E5: =C5+D5 -> 452361 | F5: =E5/33 -> 13707.909 | G5: 容積・重量比例。800個ロットでは1個あたり大きく下がる
A6: 税金 | B6: 関税 | C6: 73460 | D6: 0 | E6: =C6+D6 -> 73460 | F6: =E6/33 -> 2226.0606 | G6: 申告価額比例（推定関税率6.81%）
A7: 税金 | B7: 付加価値税 | C7: 0 | D7: 115290 | E7: =C7+D7 -> 115290 | F7: =E7/33 -> 3493.6364 | G7: 輸入VAT。課税事業者なら仕入税額控除で還付可能
A8: 通関経費 | B8: 輸入通関手数料 | C8: 30000 | D8: 3000 | E8: =C8+D8 -> 33000 | F8: =E8/33 -> 1000 | G8: ★固定（1申告あたり）。小口便ほど1個あたりが跳ね上がる
A9: 通関経費 | B9: 税関検査料 | C9: 50000 | D9: 5000 | E9: =C9+D9 -> 55000 | F9: =E9/33 -> 1666.6667 | G9: ★固定（検査1回あたり）
A10: 通関経費 | B10: 運送料 | C10: 140000 | D10: 14000 | E10: =C10+D10 -> 154000 | F10: =E10/33 -> 4666.6667 | G10: 国内配送。数量比例
A11: 通関経費 | B11: 倉庫料 | C11: 148000 | D11: 14800 | E11: =C11+D11 -> 162800 | F11: =E11/33 -> 4933.3333 | G11: 数量・保管日数比例
A12: 合計 | C12: =SUM(C5:C11) -> 875675 | D12: =SUM(D5:D11) -> 170236 | E12: =SUM(E5:E11) -> 1045911 | F12: =E12/33 -> 31694.273 | G12: 請求書合計 1,045,911W と一致
A14: 1個あたり通関費（33個便）
A15: 基準 | B15: ウォン/個 | C15: 円/個 | G15: 注記
A16: VAT込（現金支出ベース） | B16: 31694.273 | C16: =B16*'02_Assumptions'!$B$5 -> 3486.37 | G16: 実際に振り込んだ金額ベース
A17: VAT除（原価計上ベース） | B17: 26535.606 | C17: =B17*'02_Assumptions'!$B$5 -> 2918.9167 | G17: 輸入VATは仕入税額控除で還付される前提。06_Unit Economics はこちらを採用
A19: ★申告価額の乖離（要確認）
A20: 項目 | B20: 金額(W) | C20: 1個あたり(W)
A21: 輸入VAT課税標準（VAT÷10%） | B21: 1152900 | C21: 34936.364
A22: 推定CIF申告価額（課税標準−関税） | B22: 1079440 | C22: 32710.303
A23: 社内原価ベース（S18×10万＋M15×15万） | B23: 4050000 | C23: 122727.27
A24: 乖離率（申告CIF ÷ 社内原価） | B24: 0.2665284
A25: 注記
A26: ★申告CIF（推定 1個32,710W）が社内原価（1個122,727W）の26.7%しかない。考えられる理由は ①社内原価がFOB以外（金型・付属品・国内費用等）を含む ②申告価額が実取引価額と異なる。
A27: 後者の場合は追徴課税・罰則のリスクがあるため、通関士に申告価額の内訳を確認すること。前者なら社内原価の定義を整理すること。いずれにせよ800個ロット前に確定が必要。
A28: ★固定費（輸入通関手数料30,000W＋税関検査料50,000W＝88,000W税込）は数量に関わらず発生する。小口の補填便を立てるほど1個あたりが悪化する。

Sheet 23_800個通関費試算
A1: 800個ロット 通関費の積み上げ試算（仮）
A2: 33個便の実績（19_通関費用実績）を出発点に、800個・40ftコンテナ前提で置き直したもの。通関士の正式見積で差し替えてください。
A4: ① 容積の試算
A5: SKU | B5: 寸法想定 | C5: 容積(CBM/個) | D5: ミックス比率 | E5: 加重容積
A6: S | B6: 55×38×23cm | C6: ='02_Assumptions'!$B$49 -> 0.048 | D6: ='02_Assumptions'!$B$25 -> 0.4 | E6: =C6*D6 -> 0.0192 | G6: 仮定寸法
A7: M | B7: 65×45×27cm | C7: ='02_Assumptions'!$B$50 -> 0.079 | D7: ='02_Assumptions'!$B$26 -> 0.4 | E7: =C7*D7 -> 0.0316 | G7: 仮定寸法
A8: L | B8: 75×50×30cm | C8: ='02_Assumptions'!$B$51 -> 0.113 | D8: ='02_Assumptions'!$B$27 -> 0.2 | E8: =C8*D8 -> 0.0226 | G8: 仮定寸法
A9: MIX 平均 | E9: ='02_Assumptions'!$B$72 -> 0.0734 | G9: CBM/個
A10: 800個 総容積 | E10: ='02_Assumptions'!$B$73 -> 58.72 | G10: CBM。40ftHC（67CBM）1本に収まる
A12: ② 通関費の積み上げ（VAT除・仮）
A13: 項目 | B13: 金額(W) | C13: 1個あたり(W) | D13: 1個あたり(円) | E13: 性質 | F13: 33個便実績(1個) | G13: 置き方
A14: 海上運賃(40ftHC) | B14: ='02_Assumptions'!$B$52 -> 2000000 | C14: =B14/'02_Assumptions'!$B$28 -> 2500 | D14: =C14*'02_Assumptions'!$B$5 -> 275 | E14: 容積比例 | F14: 13708 | G14: 仮: USD1,500相当。33個便は少量便のため13,708W/個だった
A15: 国内運送料 | B15: 800000 | C15: =B15/'02_Assumptions'!$B$28 -> 1000 | D15: =C15*'02_Assumptions'!$B$5 -> 110 | E15: 数量比例 | F15: 4667 | G15: 仮: 33個便140,000W→大型車複数便
A16: 倉庫料 | B16: 2000000 | C16: =B16/'02_Assumptions'!$B$28 -> 2500 | D16: =C16*'02_Assumptions'!$B$5 -> 275 | E16: 数量・日数比例 | F16: 4933 | G16: 仮: 33個便148,000W→保管量増
A17: 通関手数料+検査料 | B17: 88000 | C17: =B17/'02_Assumptions'!$B$28 -> 110 | D17: =C17*'02_Assumptions'!$B$5 -> 12.1 | E17: ★固定（1申告） | F17: 2667 | G17: 実績と同額。数量で割るため1個あたりは激減
A18: 関税 | B18: =32710*'02_Assumptions'!$B$28*0.0681 -> 1782040.8 | C18: =B18/'02_Assumptions'!$B$28 -> 2227.551 | D18: =C18*'02_Assumptions'!$B$5 -> 245.03061 | E18: 申告価額比例 | F18: 2226 | G18: 仮: 申告CIF 32,710W/個（33個便水準）×6.81%
A19: 合計（VAT除） | B19: =SUM(B14:B18) -> 6670040.8 | C19: =B19/'02_Assumptions'!$B$28 -> 8337.551 | D19: =C19*'02_Assumptions'!$B$5 -> 917.13061 | F19: 26536 | G19: 33個便実績は26,536W/個（2,919円）
A21: ★採用値（丸め） | D21: ='02_Assumptions'!$B$14 -> 1000 | G21: 積み上げ917円を1,000円に丸めて02_Assumptionsに採用。通関士見積で差し替え
A23: ③ 感応度：通関費が想定より高かった場合
A24: 通関費/個(円) | B24: MIX粗利 | C24: MIX限界利益@目標CPA | D24: 損益分岐(個/月) | E24: 損益分岐(個/年)
A25: 500 | B25: ='02_Assumptions'!$B$59-'02_Assumptions'!$B$59*'02_Assumptions'!$B$12-'02_Assumptions'!$B$13-'02_Assumptions'!$B$60-A25-'02_Assumptions'!$B$16-'02_Assumptions'!$B$17 -> 8232 | C25: =B25-'02_Assumptions'!$B$18 -> 3732 | D25: =ROUNDUP('02_Assumptions'!$B$57/C25,0) -> 113 | E25: =D25*12 -> 1356 | G25: 仮
A26: 1000 | B26: ='02_Assumptions'!$B$59-'02_Assumptions'!$B$59*'02_Assumptions'!$B$12-'02_Assumptions'!$B$13-'02_Assumptions'!$B$60-A26-'02_Assumptions'!$B$16-'02_Assumptions'!$B$17 -> 7732 | C26: =B26-'02_Assumptions'!$B$18 -> 3232 | D26: =ROUNDUP('02_Assumptions'!$B$57/C26,0) -> 131 | E26: =D26*12 -> 1572 | G26: 仮
A27: 1500 | B27: ='02_Assumptions'!$B$59-'02_Assumptions'!$B$59*'02_Assumptions'!$B$12-'02_Assumptions'!$B$13-'02_Assumptions'!$B$60-A27-'02_Assumptions'!$B$16-'02_Assumptions'!$B$17 -> 7232 | C27: =B27-'02_Assumptions'!$B$18 -> 2732 | D27: =ROUNDUP('02_Assumptions'!$B$57/C27,0) -> 155 | E27: =D27*12 -> 1860 | G27: 仮
A28: 2000 | B28: ='02_Assumptions'!$B$59-'02_Assumptions'!$B$59*'02_Assumptions'!$B$12-'02_Assumptions'!$B$13-'02_Assumptions'!$B$60-A28-'02_Assumptions'!$B$16-'02_Assumptions'!$B$17 -> 6732 | C28: =B28-'02_Assumptions'!$B$18 -> 2232 | D28: =ROUNDUP('02_Assumptions'!$B$57/C28,0) -> 189 | E28: =D28*12 -> 2268 | G28: 仮
A29: 2919 | B29: ='02_Assumptions'!$B$59-'02_Assumptions'!$B$59*'02_Assumptions'!$B$12-'02_Assumptions'!$B$13-'02_Assumptions'!$B$60-A29-'02_Assumptions'!$B$16-'02_Assumptions'!$B$17 -> 5813 | C29: =B29-'02_Assumptions'!$B$18 -> 1313 | D29: =ROUNDUP('02_Assumptions'!$B$57/C29,0) -> 321 | E29: =D29*12 -> 3852 | G29: 33個便実績
A30: 注記
A31: ★固定費（通関手数料30,000W＋検査料50,000W）は1申告あたり。33個便では1個2,667Wだったが、800個なら110Wまで下がる。
A32: ★最大の不確実性は海上運賃。33個便は少量便で1個13,708Wだったが、40ftコンテナなら1個2,500W程度まで下がる想定。通関士・フォワーダーの見積で確定させること。
A33: ★申告CIF価額（32,710W/個）は33個便の水準を踏襲。19_通関費用実績で指摘した社内原価との乖離（26.7%）が未解決のため、関税額は変動しうる。

Sheet 25_チャネル別手数料
A1: チャネル別 手数料の推定（仮）
A2: ご指定の4%は自社EC/PG単体の水準に近い値です。モール販売の実態を仮で置き、加重平均を出しました。契約書・精算レポートで差し替えてください。
A4: チャネル | B4: 販売手数料 | C4: 決済手数料 | D4: ポイント負担 | E4: 合計 | F4: 売上構成比（仮） | G4: 根拠・注記
A5: ネイバースマートストア | B5: 0.02 | C5: 0.034 | D5: 0.01 | E5: =B5+C5+D5 -> 0.064 | F5: 0.35 | G5: 注文管理手数料+ネイバーペイ決済+ネイバーポイント
A6: クーパン | B6: 0.108 | C6: 0 | D6: 0.01 | E6: =B6+C6+D6 -> 0.118 | F6: 0.25 | G6: カテゴリ手数料（旅行用品帯）+クーパンキャッシュ
A7: 自社EC | B7: 0 | C7: 0.036 | D7: 0 | E7: =B7+C7+D7 -> 0.036 | F7: 0.15 | G7: PG決済手数料のみ。ご指定の4%に最も近い
A8: 楽天 | B8: 0.1 | C8: 0.031 | D8: 0.03 | E8: =B8+C8+D8 -> 0.161 | F8: 0.15 | G8: システム利用料+決済+SPU実質負担
A9: Amazon | B9: 0.1 | C9: 0 | D9: 0.005 | E9: =B9+C9+D9 -> 0.105 | F9: 0.1 | G9: 大型カテゴリ手数料+ポイント
A10: 加重平均（推定） | E10: =SUMPRODUCT(E5:E9,F5:F9) -> 0.09195 | F10: =SUM(F5:F9) -> 1 | G10: ★構成比は仮。実際のチャネル別売上で差し替えること
A12: 採用値との差（MIX・目標CPA4,500円）
A13: 前提 | B13: 手数料率 | C13: MIX粗利 | D13: MIX限界利益 | E13: 損益分岐(個/月)
A14: ご指定（採用値） | B14: 0.04 | C14: 7732 | D14: 3232 | E14: 131
A15: チャネル加重平均（推定） | B15: 0.09195 | C15: 6344.935 | D15: 1844.935 | E15: 229
A16: 注記
A17: ★この表のポイント負担は02_Assumptionsの「ポイント/クーポン負担 800円/個」と重複します。加重平均を採用する場合はどちらか一方に寄せてください。
A18: ご指定の4%を採用値として維持しています。実態が加重平均（推定11.4%）に近い場合、限界利益は大幅に減少します。
A19: ★差し替え先：各モールの契約書、月次精算レポート（手数料明細）、チャネル別売上構成。

Sheet 20_販売実績・CVR
A1: 販売実績とCVR（9/8〜9/10）
A2: ★これが今回初めて提出された販売実績。前回審査で「広告再現性20点／実績なし」とした項目が、実測値で埋まった。
A4: チャネル | B4: 期間 | C4: 訪問者 | D4: 商品検索/閲覧 | E4: カート | F4: 新規購入 | G4: 購入転換率
A5: ネイバー | B5: 9/8-9/9 | C5: 833 | F5: 0 | G5: =IF(C5=0,0,F5/C5) -> 0
A6: ネイバー | B6: 9/10 | C6: 374 | F6: 0 | G6: =IF(C6=0,0,F6/C6) -> 0
A7: クーパン | B7: 9/8-9/9 | C7: 16 | D7: 23 | E7: 0 | F7: 0 | G7: =IF(C7=0,0,F7/C7) -> 0
A8: クーパン | B8: 9/10 | C8: 5 | D8: 6 | E8: 0 | F8: 0 | G8: =IF(C8=0,0,F8/C8) -> 0
A9: 合計（3日間） | B9: 9/8-9/10 | C9: =SUM(C5:C8) -> 1228 | D9: =SUM(D5:D8) -> 29 | E9: =SUM(E5:E8) -> 0 | F9: =SUM(F5:F8) -> 0 | G9: =F9/C9 -> 0
A11: 統計的な読み方
A12: 指標 | B12: 値 | G12: 解釈
A13: ネイバー訪問（3日） | B13: 1207 | G13: 833+374
A14: 新規購入（3日） | B14: 0 | G14: 予約11件は在庫入荷前の累積分であり、この期間の新規獲得ではない
A15: 実績CVR | B15: 0 | G15: ★訪問1,207件で購入0件
A16: CVRの95%信頼上限（rule of three） | B16: 0.0024855012 | G16: 0件観測でも、真のCVRはこの値以下と推定される
A17: 日次訪問者 | B17: 402.33333 | G17: 広告再開前の水準
A18: 総レビュー件数 | B18: 25 | G18: 累計販売の下限を示す。レビュー率20〜30%なら累計83〜125個
A19: 注記
A20: ★最重要所見：在庫が無いことより、在庫があっても売れていないことの方が深刻。3日間で訪問1,207件・新規購入0件。
A21: 一方で「予約決済11件」は在庫ゼロの期間に受注できていた。＝在庫切れ＝販売停止ではない。予約販売で受注は継続できる。
A22: クーパンは訪問5〜16人・カート0件。在庫再登録前の水準であり、チャネルとして機能していない。
A23: 広告は停止期間だったため、この0.0%が広告稼働時のCVRを表すとは限らない。ただし「広告を止めないために在庫を補填する」という論拠は、この実績では支えられない。

Sheet 21_補填判断
A1: 次回入荷までの在庫補填 判断
A2: 現在庫22個／次回入荷 11月頭出荷（韓国着11月中旬想定）＝約65日。補填すべきか、いくらかかるかを数値化する。
A4: ① 次回入荷までの販売予測（CVR水準別）
A5: CVR前提 | B5: 根拠 | C5: 想定訪問者 | D5: 予測販売数 | E5: 現在庫 | F5: 不足数量 | G5: 判定
A6: 0 | B6: 実績（3日間 購入0件） | C6: ='02_Assumptions'!$B$40/3*'02_Assumptions'!$B$39 -> 24140 | D6: =C6*A6 -> 0 | E6: ='02_Assumptions'!$B$38 -> 22 | F6: =MAX(0,D6-E6) -> 0 | G6: 補填不要
A7: 0.0024855012 | B7: 95%信頼上限 rule of three | C7: ='02_Assumptions'!$B$40/3*'02_Assumptions'!$B$39 -> 24140 | D7: =C7*A7 -> 60 | E7: ='02_Assumptions'!$B$38 -> 22 | F7: =MAX(0,D7-E7) -> 38 | G7: 要検討
A8: 0.005 | B8: EC物販の下限水準 | C8: ='02_Assumptions'!$B$40/3*'02_Assumptions'!$B$39 -> 24140 | D8: =C8*A8 -> 120.7 | E8: ='02_Assumptions'!$B$38 -> 22 | F8: =MAX(0,D8-E8) -> 98.7 | G8: 要検討
A9: 0.01 | B9: 社内目標水準 | C9: ='02_Assumptions'!$B$40/3*'02_Assumptions'!$B$39 -> 24140 | D9: =C9*A9 -> 241.4 | E9: ='02_Assumptions'!$B$38 -> 22 | F9: =MAX(0,D9-E9) -> 219.4 | G9: 要検討
A11: ② パターン1｜日本→韓国（EMS／ハンドキャリー）
A12: 手段 | B12: 1回あたりコスト | C12: 1回の輸送個数 | D12: 1個あたりコスト | E12: 限界利益 | F12: 限界利益の何倍 | G12: 判定
A13: EMS（通常運賃） | B13: ='02_Assumptions'!$B$42 -> 18931 | C13: =1 -> 1 | D13: =B13/C13 -> 18931 | E13: ='02_Assumptions'!$B$63 -> 3232 | F13: =D13/E13 -> 5.8573639 | G13: 赤字
A14: EMS（記載の約2倍運賃） | B14: ='02_Assumptions'!$B$42*2 -> 37862 | C14: =1 -> 1 | D14: =B14/C14 -> 37862 | E14: ='02_Assumptions'!$B$63 -> 3232 | F14: =D14/E14 -> 11.714728 | G14: 赤字
A15: ハンドキャリー | B15: ='02_Assumptions'!$B$44 -> 97038 | C15: ='02_Assumptions'!$B$45 -> 3 | D15: =B15/C15 -> 32346 | E15: ='02_Assumptions'!$B$63 -> 3232 | F15: =D15/E15 -> 10.008045 | G15: 赤字
A17: ③ パターン2｜中国→韓国（小口の別便）
A18: 項目 | B18: 金額 | G18: 注記
A19: 固定的通関費（手数料+検査料・税込） | B19: 9680 | G19: 数量に関わらず1便ごとに発生
A20: 33個便の実績 1個あたり（VAT込） | B20: 3486.37 | G20: 実績値
A21: 11個の小口便にした場合の固定費按分 | B21: 880 | G21: 固定費だけで1個8,800円。33個便の2.6倍
A22: 混載便(LCL)運賃 | G22: ★未提出。フォワーダー見積が必要
A23: コンテナ空きスペースによる損失 | G23: ★算出不能。コンテナ単価・積載可能数・1個あたり容積が未提出
A24: 実質コスト/個 | G24: ★上記2項目が埋まれば自動算出可能
A26: ④ 最終判断：4点の数値化（不足を最大11個と置いた場合）
A27: 判断項目 | B27: 金額／数量 | G27: 注記
A28: ① 販売機会損失 | B28: 35552 | G28: 11個 × 限界利益3,232円。予約販売を継続すればさらに小さくなる
A29: ② 追加運賃（EMS案） | B29: 208241 | G29: 11梱包 × 18,931円
A30: ② 追加運賃（ハンドキャリー案） | B30: 388152 | G30: 4往復 × 97,038円
A31: ③ 空きスペース損失 | G31: ★算出不能（データ未提出）
A32: ④ 必要在庫数 | B32: 11 | G32: ★CVR実績0%のため0〜11個の幅。確定不能
A33: 補填した場合の差引損失（EMS案） | B33: 172689 | G33: 補填コスト − 機会損失。プラス＝補填するほど損をする
A35: 結論
A36: 【補填しない】が最も利益が残る。EMSで11個補填すると208,241円かかるのに対し、失う限界利益は27,644円。補填すると差引180,597円の損失増。
A37: ハンドキャリーは1個あたり32,346円（3個持込時）。限界利益2,513円の12.9倍であり、経済合理性がない。
A38: 中国→韓国の小口別便も、固定的通関費88,000W（約9,680円）が1便ごとに発生するため、11個規模では非経済的。
A39: 代わりに：①ネイバーは予約販売を継続して受注を溜める（在庫ゼロでも11件受注できた実績あり） ②クーパンは残22個を割り当てて再開 ③11月入荷分でまとめて発送。
A40: ★ただし本当のボトルネックは在庫ではなくCVR 0.0%。訪問1,207件・購入0件を直す方が、補填11個より桁違いにインパクトが大きい。

Sheet 22_必要経費3ヶ月
A1: 必要経費 3ヶ月分の算出（@Kokoa依頼分）
A2: 2026-09〜11の3ヶ月。黄色＝金額が未提示のため入力待ち。ウォン建てと円換算を併記。
A4: ① 立替が必要な費用
A5: 項目 | B5: 金額(W) | C5: 回数 | D5: 小計(W) | E5: 円換算 | F5: 状態 | G5: 注記
A6: 通関費用（9/10支払済） | B6: 1045911 | C6: 1 | D6: =IF(B6="","",B6*C6) -> 1045911 | E6: =IF(D6="","",D6*'02_Assumptions'!$B$5) -> 115050.21 | F6: 支払済 | G6: LJ関税事務所 I26-100263M。33個分
A7: 外注費用 | C7: 1 | D7: =IF(B7="","",B7*C7) | E7: =IF(D7="","",D7*'02_Assumptions'!$B$5) | F7: ★未提示 | G7: ★金額をご提示ください
A8: 立替 小計 | D8: =SUM(D6:D7) -> 1045911 | E8: =D8*'02_Assumptions'!$B$5 -> 115050.21
A10: ② 固定費（3ヶ月分）
A11: 項目 | B11: 月額(W) | C11: ヶ月 | D11: 小計(W) | E11: 円換算 | F11: 根拠 | G11: 注記
A12: 給与 | B12: 3000000 | C12: 3 | D12: =B12*C12 -> 9000000 | E12: =D12*'02_Assumptions'!$B$5 -> 990000 | F12: 月給300万ウォン基準
A13: 家賃 | B13: 550000 | C13: 3 | D13: =B13*C13 -> 1650000 | E13: =D13*'02_Assumptions'!$B$5 -> 181500 | F13: 既存の月間支出
A14: 管理費 | B14: 165000 | C14: 3 | D14: =B14*C14 -> 495000 | E14: =D14*'02_Assumptions'!$B$5 -> 54450 | F14: 既存の月間支出
A15: 税理士費用 | B15: 110000 | C15: 3 | D15: =B15*C15 -> 330000 | E15: =D15*'02_Assumptions'!$B$5 -> 36300 | F15: 既存の月間支出
A16: 固定費 小計 | D16: =SUM(D12:D15) -> 11475000 | E16: =D16*'02_Assumptions'!$B$5 -> 1262250
A18: ③ 変動費・広告費（3ヶ月分）
A19: 項目 | B19: 月額(W) | C19: ヶ月 | D19: 小計(W) | E19: 円換算 | F19: 根拠 | G19: 注記
A20: メタ広告費 | B20: 3960000 | C20: 3 | D20: =IF(B20="","",B20*C20) -> 11880000 | E20: =IF(D20="","",D20*'02_Assumptions'!$B$5) -> 1306800 | F20: 7/18-8/19 実績（付加価値税込） | G20: ★この水準を継続するか要判断。CVR0%のまま出すと全額が損失
A21: 交通費 | B21: 256667 | C21: 3 | D21: =IF(B21="","",B21*C21) -> 770001 | E21: =IF(D21="","",D21*'02_Assumptions'!$B$5) -> 84700.11 | F21: 実績770,000W÷3回
A22: 宅配費 | B22: 60043 | C22: 3 | D22: =IF(B22="","",B22*C22) -> 180129 | E22: =IF(D22="","",D22*'02_Assumptions'!$B$5) -> 19814.19 | F22: 実績420,300W÷7回
A23: EMS | B23: 172100 | C23: 3 | D23: =IF(B23="","",B23*C23) -> 516300 | E23: =IF(D23="","",D23*'02_Assumptions'!$B$5) -> 56793 | F23: 実績688,400W÷4回 | G23: 送料・物流費用
A24: レビュー送料・手数料 | C24: 3 | D24: =IF(B24="","",B24*C24) | E24: =IF(D24="","",D24*'02_Assumptions'!$B$5) | F24: ★未提示 | G24: ★1件あたり単価と月間件数をご提示ください
A25: ソフトウェア（Canva等） | B25: 9900 | C25: 3 | D25: =IF(B25="","",B25*C25) -> 29700 | E25: =IF(D25="","",D25*'02_Assumptions'!$B$5) -> 3267 | F25: 実績29,700W÷3回
A26: その他運営費 | B26: 21700 | C26: 3 | D26: =IF(B26="","",B26*C26) -> 65100 | E26: =IF(D26="","",D26*'02_Assumptions'!$B$5) -> 7161 | F26: 実績108,500W÷5回
A27: 変動費 小計 | D27: =SUM(D20:D26) -> 13441230 | E27: =D27*'02_Assumptions'!$B$5 -> 1478535.3
A29: ④ 仕入・通関（800個ロット）
A30: 項目 | B30: 金額(W) | D30: 小計(W) | E30: 円換算 | F30: 状態 | G30: 注記
A31: 800個 仕入原価（仮定ミックス） | B31: 112000000 | D31: =B31 -> 112000000 | E31: =D31*'02_Assumptions'!$B$5 -> 12320000 | F31: 仮定 | G31: ★SKU内訳・数量割引後単価が未提示。S40:M40:L20で仮置き
A32: 800個 通関費用 | F32: ★未提示 | G32: ★通関士から見積が出ているとのこと。金額をご提示いただければ即座に総額が確定します
A33: 仕入・通関 小計 | D33: =SUM(D31:D32) -> 112000000 | E33: =D33*'02_Assumptions'!$B$5 -> 12320000
A35: ⑤ 3ヶ月 総所要資金
A36: 区分 | B36: 金額(W) | E36: 円換算 | G36: 注記
A37: ① 立替（通関・外注） | B37: =D10 -> 1045911 | E37: =B37*'02_Assumptions'!$B$5 -> 115050.21 | G37: 外注費が未提示のため暫定
A38: ② 固定費 3ヶ月 | B38: =D16 -> 11475000 | E38: =B38*'02_Assumptions'!$B$5 -> 1262250
A39: ③ 変動費・広告費 3ヶ月 | B39: =D27 -> 13441230 | E39: =B39*'02_Assumptions'!$B$5 -> 1478535.3 | G39: レビュー送料が未提示のため暫定
A40: ④ 仕入・通関（800個） | B40: =D33 -> 112000000 | E40: =B40*'02_Assumptions'!$B$5 -> 12320000 | G40: ★通関費が未提示のため大幅に過少
A41: 合計（暫定） | B41: =SUM(B37:B40) -> 137962141 | E41: =B41*'02_Assumptions'!$B$5 -> 15175836 | G41: ★未提示3項目（外注費・レビュー送料・800個通関費）が入れば確定
A42: 注記
A43: ★未提示のため総額が確定できない3項目：①外注費用 ②レビュー送料・手数料の単価と件数 ③800個の通関費用（通関士見積）。
A44: ★メタ広告費 月396万W（約43.6万円）×3ヶ月＝約131万円。現在のCVR 0.0%のまま出稿すると、この全額が回収不能になる。広告再開の前にCVRを直すこと。
A45: 固定費3ヶ月 1,147.5万W（約126万円）は売上に関わらず発生する。これを賄うには 22_必要経費 とは別に 06_Unit Economics の損益分岐（月168個）が必要。

Sheet 03_Market
A1: 市場分析 TAM / SAM / SOM（仮）
A2: 韓国市場を人口と買替サイクルから積み上げた仮の試算です。統計庁・矢野経済・モールランキングで差し替えてください。
A4: ① TAM の積み上げ（仮）
A5: 項目 | B5: 値 | C5: 単位 | D5: 出典 | E5: 置き方
A6: 韓国人口 | B6: 51700000 | C6: 人 | D6: 統計庁（仮引用） | E6: 要出典確認
A7: 世帯数 | B7: 22000000 | C7: 世帯 | D7: 統計庁（仮引用） | E7: 要出典確認
A8: 1世帯あたり保有数 | B8: 1.5 | C8: 個 | D8: 仮 | E8: 要確認
A9: 買替サイクル | B9: 7 | C9: 年 | D9: 仮 | E9: 5〜10年の中央値
A10: 年間需要数量 | B10: =B7*B8/B9 -> 4714285.7 | C10: 個/年 | D10: 算出 | E10: 世帯×保有数÷サイクル
A11: 平均単価 | B11: 150000 | C11: ウォン | D11: 仮 | E11: 中価格帯の想定
A12: TAM（年間市場規模） | B12: =B10*B11 -> 7.0714286e+11 | C12: ウォン/年 | D12: 算出 | E12: 需要数量×平均単価
A14: ② SAM / SOM（仮）
A15: 区分 | B15: 算定 | C15: 金額(ウォン/年) | D15: 数量換算(個/年) | E15: 注記
A16: SAM | B16: TAM × EC比率40% × 中価格帯25% | C16: =B12*0.4*0.25 -> 7.0714286e+10 | D16: =C16/150000 -> 471428.57 | E16: EC比率・価格帯比率とも仮
A17: SOM（仮シェア0.1%） | B17: SAM × 0.1% | C17: =C16*0.001 -> 70714286 | D17: =C17/150000 -> 471.42857 | E17: 新規参入ブランドの現実的な初年度シェア
A18: 損益分岐に必要な数量 | B18: 06_Unit Economics より | C18: ='02_Assumptions'!$B$68*'02_Assumptions'!$B$59/'02_Assumptions'!$B$5 -> 3.8156727e+08 | D18: ='02_Assumptions'!$B$68 -> 1572 | E18: ★SOM（仮）を上回るかが論点
A20: ③ 市場の質（要調査項目）
A21: 項目 | B21: 仮の見立て | C21: 確度 | D21: 調査方法 | E21: 注記
A22: 市場成長率 | B22: 0〜3%（横ばい） | C22: 仮 | D22: 統計庁・業界レポート | E22: コロナ後の旅行需要回復は一巡
A23: 検索需要 | B23: 要調査 | C23: — | D23: ネイバーキーワードツール／Googleキーワードプランナー | E23: 「여행가방」「캐리어」の月間検索数
A24: 季節性 | B24: GW前・夏休み前・年末年始前に山 | C24: 仮 | D24: 自社の月次売上／モールのカテゴリ推移 | E24: 閑散期の在庫滞留を発注量に織り込む
A25: 価格帯分布 | B25: 10〜20万Wが最大ボリューム | C25: 仮 | D25: ネイバー/クーパンのカテゴリランキング | E25: 自社の21,900〜33,900円＝約20〜31万Wは中〜上位帯
A26: レビュー件数の分布 | B26: 上位SKUは1,000件超 | C26: 仮 | D26: モールのランキング上位30SKU | E26: 自社25件は初期段階
A27: 注記
A28: ★このシートは全て仮の積み上げです。TAM/SAM/SOMはいずれも出典未確認。
A29: ★最重要の論点：損益分岐に必要な年1572個が、仮のSOM（年471個）を大きく上回っています。
A30: 差し替え先：統計庁「가계동향조사」、矢野経済/富士経済の鞄市場調査、ネイバー/クーパンのカテゴリランキング上位SKUの推定月販。

Sheet 04_Competitor
A1: 競合分析（仮）
A2: ★競合4社は仮のプロファイルです。ネイバー/クーパンのカテゴリランキングから実データで差し替えてください。
A4: 競合 | B4: 区分 | C4: 価格帯(W) | D4: レビュー数 | E4: 推定月販 | F4: 推定月商(W) | G4: 参入時期 | H4: 強み／自社との差
A5: 競合A（同価格帯ECブランド） | B5: 直接 | C5: 180,000〜300,000 | D5: 1200 | E5: 150 | F5: 約34,500,000 | G5: 2〜3年前 | H5: レビュー1,200件。指名検索あり。後発が正面から勝つのは困難
A6: 競合B（ノーブランド廉価） | B6: 直接 | C6: 80,000〜150,000 | D6: 3500 | E6: 400 | F6: 約46,000,000 | G6: 5年以上前 | H6: 価格。ここに引き込まれると粗利21.8%が即消える
A7: 競合C（大手ブランド） | B7: 間接 | C7: 350,000〜800,000 | D7: 800 | E7: 80 | F7: 約46,000,000 | G7: 10年以上 | H7: ブランド指名。広告で正面衝突するとCPAが上がる
A8: 競合D（小売・量販） | B8: 間接 | C8: 100,000〜300,000 | D8: — | E8: — | F8: — | G8: — | H8: 実店舗で触って買える。EC単独の最大の弱点
A9: レンタル | B9: 代替 | C9: 20,000〜80,000/回 | D9: — | E9: — | F9: — | G9: — | H9: 年1回しか旅行しない層を奪う
A10: 買わない／借りる | B10: 代替 | C10: 0 | D10: — | E10: — | F10: — | G10: — | H10: Vitamin商材の宿命。購入を先送りされる
A12: 自社ポジション（実績）
A13: 項目 | B13: 自社 | C13: 競合A | D13: 競合B
A14: 価格帯(W) | B14: 約200,000〜310,000 | C14: 180,000〜300,000 | D14: 80,000〜150,000 | H14: ほぼ競合Aと同帯
A15: レビュー件数 | B15: 25 | C15: 1200 | D15: 3500 | H15: ★48分の1〜140分の1。最大の劣位
A16: 月販（直近） | B16: 0 | C16: 150 | D16: 400 | H16: ★直近3日の新規購入0件
A17: 参入時期 | B17: 2025年12月 | C17: 2〜3年前 | D17: 5年以上前 | H17: 後発
A19: 競合が自社をコピーした場合
A20: ・スーツケースは意匠以外に参入障壁がほぼない。OEM元が同じなら競合も同じ商品を出せる。
A21: ・自社が広告で需要を掘り起こした瞬間、同型番の廉価版が相乗りしてくる構造。
A22: ・防御策は「レビュー数」「ブランド想起」「独自機能の意匠登録」の3つのみ。現状レビュー25件で、いずれも未確立。
A23: 注記
A24: ★競合A〜Dの数値は全て仮。ネイバー/クーパンのカテゴリランキング上位30SKUを実測して差し替えること。
A25: 調査方法：ランキング上位SKUの ①価格 ②レビュー件数 ③レビュー増加ペース（月次差分＝推定月販の代理指標）を記録する。

Sheet 05_Pricing
A1: 価格設計と値引き耐性
A2: 売価S/Mは確定、Lは仮定。値引き耐性＝どこまで下げると1個売るごとに赤字になるか
A4: SKU | B4: 売価 | C4: 原価(W) | D4: 原価(円) | E4: 粗利 | F4: 粗利率 | G4: 限界益@目標CPA | H4: 限界益@許容CPA | L4: 注記
A5: S | B5: ='02_Assumptions'!$B$6 -> 21900 | C5: ='02_Assumptions'!$B$9 -> 100000 | D5: ='02_Assumptions'!$B$9*'02_Assumptions'!$B$5 -> 11000 | E5: =B5-B5*'02_Assumptions'!$B$12-'02_Assumptions'!$B$13-D5-'02_Assumptions'!$B$14-'02_Assumptions'!$B$16-'02_Assumptions'!$B$17 -> 7524 | F5: =E5/B5 -> 0.34356164 | G5: =E5-'02_Assumptions'!$B$18 -> 3024 | H5: =E5-'02_Assumptions'!$B$19 -> 1524 | L5: 確定
A6: M | B6: ='02_Assumptions'!$B$7 -> 27900 | C6: ='02_Assumptions'!$B$10 -> 150000 | D6: ='02_Assumptions'!$B$10*'02_Assumptions'!$B$5 -> 16500 | E6: =B6-B6*'02_Assumptions'!$B$12-'02_Assumptions'!$B$13-D6-'02_Assumptions'!$B$14-'02_Assumptions'!$B$16-'02_Assumptions'!$B$17 -> 7784 | F6: =E6/B6 -> 0.27899642 | G6: =E6-'02_Assumptions'!$B$18 -> 3284 | H6: =E6-'02_Assumptions'!$B$19 -> 1784 | L6: 確定
A7: L | B7: ='02_Assumptions'!$B$8 -> 33900 | C7: ='02_Assumptions'!$B$11 -> 200000 | D7: ='02_Assumptions'!$B$11*'02_Assumptions'!$B$5 -> 22000 | E7: =B7-B7*'02_Assumptions'!$B$12-'02_Assumptions'!$B$13-D7-'02_Assumptions'!$B$14-'02_Assumptions'!$B$16-'02_Assumptions'!$B$17 -> 8044 | F7: =E7/B7 -> 0.23728614 | G7: =E7-'02_Assumptions'!$B$18 -> 3544 | H7: =E7-'02_Assumptions'!$B$19 -> 2044 | L7: ★売価・原価とも仮定
A9: 値引き耐性（@目標CPA4,500での限界利益）
A10: SKU | B10: 定価 | C10: ▲5% | D10: ▲10% | E10: ▲15% | F10: ▲20% | G10: ▲25% | H10: 限界益ゼロ点
A11: S | B11: =$B$5*(1-0)-$B$5*(1-0)*'02_Assumptions'!$B$12-'02_Assumptions'!$B$13-$D$5-'02_Assumptions'!$B$14-'02_Assumptions'!$B$16-'02_Assumptions'!$B$17-'02_Assumptions'!$B$18 -> 3024 | C11: =$B$5*(1-0.05)-$B$5*(1-0.05)*'02_Assumptions'!$B$12-'02_Assumptions'!$B$13-$D$5-'02_Assumptions'!$B$14-'02_Assumptions'!$B$16-'02_Assumptions'!$B$17-'02_Assumptions'!$B$18 -> 1972.8 | D11: =$B$5*(1-0.1)-$B$5*(1-0.1)*'02_Assumptions'!$B$12-'02_Assumptions'!$B$13-$D$5-'02_Assumptions'!$B$14-'02_Assumptions'!$B$16-'02_Assumptions'!$B$17-'02_Assumptions'!$B$18 -> 921.6 | E11: =$B$5*(1-0.15)-$B$5*(1-0.15)*'02_Assumptions'!$B$12-'02_Assumptions'!$B$13-$D$5-'02_Assumptions'!$B$14-'02_Assumptions'!$B$16-'02_Assumptions'!$B$17-'02_Assumptions'!$B$18 -> -129.6 | F11: =$B$5*(1-0.2)-$B$5*(1-0.2)*'02_Assumptions'!$B$12-'02_Assumptions'!$B$13-$D$5-'02_Assumptions'!$B$14-'02_Assumptions'!$B$16-'02_Assumptions'!$B$17-'02_Assumptions'!$B$18 -> -1180.8 | G11: =$B$5*(1-0.25)-$B$5*(1-0.25)*'02_Assumptions'!$B$12-'02_Assumptions'!$B$13-$D$5-'02_Assumptions'!$B$14-'02_Assumptions'!$B$16-'02_Assumptions'!$B$17-'02_Assumptions'!$B$18 -> -2232 | H11: 0.144
A12: M | B12: =$B$6*(1-0)-$B$6*(1-0)*'02_Assumptions'!$B$12-'02_Assumptions'!$B$13-$D$6-'02_Assumptions'!$B$14-'02_Assumptions'!$B$16-'02_Assumptions'!$B$17-'02_Assumptions'!$B$18 -> 3284 | C12: =$B$6*(1-0.05)-$B$6*(1-0.05)*'02_Assumptions'!$B$12-'02_Assumptions'!$B$13-$D$6-'02_Assumptions'!$B$14-'02_Assumptions'!$B$16-'02_Assumptions'!$B$17-'02_Assumptions'!$B$18 -> 1944.8 | D12: =$B$6*(1-0.1)-$B$6*(1-0.1)*'02_Assumptions'!$B$12-'02_Assumptions'!$B$13-$D$6-'02_Assumptions'!$B$14-'02_Assumptions'!$B$16-'02_Assumptions'!$B$17-'02_Assumptions'!$B$18 -> 605.6 | E12: =$B$6*(1-0.15)-$B$6*(1-0.15)*'02_Assumptions'!$B$12-'02_Assumptions'!$B$13-$D$6-'02_Assumptions'!$B$14-'02_Assumptions'!$B$16-'02_Assumptions'!$B$17-'02_Assumptions'!$B$18 -> -733.6 | F12: =$B$6*(1-0.2)-$B$6*(1-0.2)*'02_Assumptions'!$B$12-'02_Assumptions'!$B$13-$D$6-'02_Assumptions'!$B$14-'02_Assumptions'!$B$16-'02_Assumptions'!$B$17-'02_Assumptions'!$B$18 -> -2072.8 | G12: =$B$6*(1-0.25)-$B$6*(1-0.25)*'02_Assumptions'!$B$12-'02_Assumptions'!$B$13-$D$6-'02_Assumptions'!$B$14-'02_Assumptions'!$B$16-'02_Assumptions'!$B$17-'02_Assumptions'!$B$18 -> -3412 | H12: 0.123
A13: L | B13: =$B$7*(1-0)-$B$7*(1-0)*'02_Assumptions'!$B$12-'02_Assumptions'!$B$13-$D$7-'02_Assumptions'!$B$14-'02_Assumptions'!$B$16-'02_Assumptions'!$B$17-'02_Assumptions'!$B$18 -> 3544 | C13: =$B$7*(1-0.05)-$B$7*(1-0.05)*'02_Assumptions'!$B$12-'02_Assumptions'!$B$13-$D$7-'02_Assumptions'!$B$14-'02_Assumptions'!$B$16-'02_Assumptions'!$B$17-'02_Assumptions'!$B$18 -> 1916.8 | D13: =$B$7*(1-0.1)-$B$7*(1-0.1)*'02_Assumptions'!$B$12-'02_Assumptions'!$B$13-$D$7-'02_Assumptions'!$B$14-'02_Assumptions'!$B$16-'02_Assumptions'!$B$17-'02_Assumptions'!$B$18 -> 289.6 | E13: =$B$7*(1-0.15)-$B$7*(1-0.15)*'02_Assumptions'!$B$12-'02_Assumptions'!$B$13-$D$7-'02_Assumptions'!$B$14-'02_Assumptions'!$B$16-'02_Assumptions'!$B$17-'02_Assumptions'!$B$18 -> -1337.6 | F13: =$B$7*(1-0.2)-$B$7*(1-0.2)*'02_Assumptions'!$B$12-'02_Assumptions'!$B$13-$D$7-'02_Assumptions'!$B$14-'02_Assumptions'!$B$16-'02_Assumptions'!$B$17-'02_Assumptions'!$B$18 -> -2964.8 | G13: =$B$7*(1-0.25)-$B$7*(1-0.25)*'02_Assumptions'!$B$12-'02_Assumptions'!$B$13-$D$7-'02_Assumptions'!$B$14-'02_Assumptions'!$B$16-'02_Assumptions'!$B$17-'02_Assumptions'!$B$18 -> -4592 | H13: 0.109
A14: 注記
A15: 通関費算入後、S は約▲11%、M/L は約▲9%で限界利益がゼロ。値引き余地はほとんど無い。
A16: クーポン・ポイント還元は実質値引き。楽天SPU等で10%相当を負担すると M/L は赤字圏に入る。
A17: ※ 02_Assumptions の「ポイント/クーポン負担」を実額で入れれば、この表に自動反映されます。

Sheet 06_Unit Economics
A1: ユニットエコノミクス（1個あたり）
A2: 黄色の0円列は★未算入＝現在の利益は過大評価。02_Assumptions で実額を入れると全て連動します。
A4: SKU | B4: 売価 | C4: 仕入原価 | D4: 国際送料/関税/倉庫 | E4: 返品引当 | F4: ポイント | G4: 国内送料 | H4: モール/決済手数料 | L4: 広告CPA | M4: 限界利益 | N4: 限界利益率 | O4: 注記
A5: S | B5: ='02_Assumptions'!$B$6 -> 21900 | C5: ='02_Assumptions'!$B$9*'02_Assumptions'!$B$5 -> 11000 | D5: ='02_Assumptions'!$B$14 -> 1000 | E5: ='02_Assumptions'!$B$16 -> 400 | F5: ='02_Assumptions'!$B$17 -> 800 | G5: ='02_Assumptions'!$B$13 -> 300 | H5: =B5*'02_Assumptions'!$B$12 -> 876 | L5: ='02_Assumptions'!$B$18 -> 4500 | M5: =B5-C5-D5-E5-F5-G5-H5-L5 -> 3024 | N5: =M5/B5 -> 0.13808219 | O5: ★未算入項目あり
A6: M | B6: ='02_Assumptions'!$B$7 -> 27900 | C6: ='02_Assumptions'!$B$10*'02_Assumptions'!$B$5 -> 16500 | D6: ='02_Assumptions'!$B$14 -> 1000 | E6: ='02_Assumptions'!$B$16 -> 400 | F6: ='02_Assumptions'!$B$17 -> 800 | G6: ='02_Assumptions'!$B$13 -> 300 | H6: =B6*'02_Assumptions'!$B$12 -> 1116 | L6: ='02_Assumptions'!$B$18 -> 4500 | M6: =B6-C6-D6-E6-F6-G6-H6-L6 -> 3284 | N6: =M6/B6 -> 0.11770609 | O6: ★未算入項目あり
A7: L | B7: ='02_Assumptions'!$B$8 -> 33900 | C7: ='02_Assumptions'!$B$11*'02_Assumptions'!$B$5 -> 22000 | D7: ='02_Assumptions'!$B$14 -> 1000 | E7: ='02_Assumptions'!$B$16 -> 400 | F7: ='02_Assumptions'!$B$17 -> 800 | G7: ='02_Assumptions'!$B$13 -> 300 | H7: =B7*'02_Assumptions'!$B$12 -> 1356 | L7: ='02_Assumptions'!$B$18 -> 4500 | M7: =B7-C7-D7-E7-F7-G7-H7-L7 -> 3544 | N7: =M7/B7 -> 0.10454277 | O7: ★未算入項目あり
A8: MIX | B8: ='02_Assumptions'!$B$59 -> 26700 | C8: ='02_Assumptions'!$B$60 -> 15400 | D8: ='02_Assumptions'!$B$14 -> 1000 | E8: ='02_Assumptions'!$B$16 -> 400 | F8: ='02_Assumptions'!$B$17 -> 800 | G8: ='02_Assumptions'!$B$13 -> 300 | H8: =B8*'02_Assumptions'!$B$12 -> 1068 | L8: ='02_Assumptions'!$B$18 -> 4500 | M8: ='02_Assumptions'!$B$63 -> 3232 | N8: ='02_Assumptions'!$B$66 -> 0.12104869 | O8: 仮定ミックス S40:M40:L20
A10: 感応度①：未算入コストを入れた場合（MIX・目標CPA）
A11: 追加コスト/個 | B11: 限界利益 | C11: 限界利益率 | D11: 損益分岐(個/月)
A12: 0 | B12: ='02_Assumptions'!$B$63-A12 -> 3232 | C12: =B12/'02_Assumptions'!$B$59 -> 0.12104869 | D12: =IF(B12<=0,"—",ROUNDUP('02_Assumptions'!$B$57/B12,0)) -> 131
A13: 500 | B13: ='02_Assumptions'!$B$63-A13 -> 2732 | C13: =B13/'02_Assumptions'!$B$59 -> 0.1023221 | D13: =IF(B13<=0,"—",ROUNDUP('02_Assumptions'!$B$57/B13,0)) -> 155
A14: 1000 | B14: ='02_Assumptions'!$B$63-A14 -> 2232 | C14: =B14/'02_Assumptions'!$B$59 -> 0.083595506 | D14: =IF(B14<=0,"—",ROUNDUP('02_Assumptions'!$B$57/B14,0)) -> 189
A15: 1500 | B15: ='02_Assumptions'!$B$63-A15 -> 1732 | C15: =B15/'02_Assumptions'!$B$59 -> 0.064868914 | D15: =IF(B15<=0,"—",ROUNDUP('02_Assumptions'!$B$57/B15,0)) -> 243
A16: 2000 | B16: ='02_Assumptions'!$B$63-A16 -> 1232 | C16: =B16/'02_Assumptions'!$B$59 -> 0.046142322 | D16: =IF(B16<=0,"—",ROUNDUP('02_Assumptions'!$B$57/B16,0)) -> 342
A17: 3000 | B17: ='02_Assumptions'!$B$63-A17 -> 232 | C17: =B17/'02_Assumptions'!$B$59 -> 0.0086891386 | D17: =IF(B17<=0,"—",ROUNDUP('02_Assumptions'!$B$57/B17,0)) -> 1814
A19: 感応度②：モール手数料率（S・目標CPA）
A20: 手数料率 | B20: 粗利 | C20: 粗利率 | D20: 限界利益 | E20: 限界利益率
A21: 0.04 | B21: ='02_Assumptions'!$B$6-'02_Assumptions'!$B$6*A21-'02_Assumptions'!$B$13-'02_Assumptions'!$B$9*'02_Assumptions'!$B$5-'02_Assumptions'!$B$14-'02_Assumptions'!$B$16-'02_Assumptions'!$B$17 -> 7524 | C21: =B21/'02_Assumptions'!$B$6 -> 0.34356164 | D21: =B21-'02_Assumptions'!$B$18 -> 3024 | E21: =D21/'02_Assumptions'!$B$6 -> 0.13808219
A22: 0.08 | B22: ='02_Assumptions'!$B$6-'02_Assumptions'!$B$6*A22-'02_Assumptions'!$B$13-'02_Assumptions'!$B$9*'02_Assumptions'!$B$5-'02_Assumptions'!$B$14-'02_Assumptions'!$B$16-'02_Assumptions'!$B$17 -> 6648 | C22: =B22/'02_Assumptions'!$B$6 -> 0.30356164 | D22: =B22-'02_Assumptions'!$B$18 -> 2148 | E22: =D22/'02_Assumptions'!$B$6 -> 0.098082192
A23: 0.1 | B23: ='02_Assumptions'!$B$6-'02_Assumptions'!$B$6*A23-'02_Assumptions'!$B$13-'02_Assumptions'!$B$9*'02_Assumptions'!$B$5-'02_Assumptions'!$B$14-'02_Assumptions'!$B$16-'02_Assumptions'!$B$17 -> 6210 | C23: =B23/'02_Assumptions'!$B$6 -> 0.28356164 | D23: =B23-'02_Assumptions'!$B$18 -> 1710 | E23: =D23/'02_Assumptions'!$B$6 -> 0.078082192
A24: 0.12 | B24: ='02_Assumptions'!$B$6-'02_Assumptions'!$B$6*A24-'02_Assumptions'!$B$13-'02_Assumptions'!$B$9*'02_Assumptions'!$B$5-'02_Assumptions'!$B$14-'02_Assumptions'!$B$16-'02_Assumptions'!$B$17 -> 5772 | C24: =B24/'02_Assumptions'!$B$6 -> 0.26356164 | D24: =B24-'02_Assumptions'!$B$18 -> 1272 | E24: =D24/'02_Assumptions'!$B$6 -> 0.058082192
A25: 0.15 | B25: ='02_Assumptions'!$B$6-'02_Assumptions'!$B$6*A25-'02_Assumptions'!$B$13-'02_Assumptions'!$B$9*'02_Assumptions'!$B$5-'02_Assumptions'!$B$14-'02_Assumptions'!$B$16-'02_Assumptions'!$B$17 -> 5115 | C25: =B25/'02_Assumptions'!$B$6 -> 0.23356164 | D25: =B25-'02_Assumptions'!$B$18 -> 615 | E25: =D25/'02_Assumptions'!$B$6 -> 0.028082192
A26: 注記
A27: LTV/CAC：スーツケースは買替サイクル5〜10年の低頻度商材。LTV≒初回購入額として評価する。
A28: 売上ベース LTV/CAC＝26,700÷4,500＝5.9倍。ただし限界利益ベースでは 2,513÷4,500＝0.56倍。1を下回る＝広告費を回収できていない。
A29: 回収期間：1個単位では即時。ただし800個ロットでは全量販売完了まで12ヶ月以上（12_Inventory参照）。
A30: ★通関費2,919円/個（9/10実績）を算入した結果、損益分岐は78→168個/月に悪化した。返品引当・ポイント負担はまだ未算入。

Sheet 07_Sales Forecast
A1: 販売計画（12ヶ月・標準ケース）
A2: ★販売実績が未提出のため、「800個を12ヶ月で消化」＝月58個を標準として置いた計画値。実績ではない。
A4: 月 | B4: 販売数 | C4: 平均単価 | D4: 売上 | E4: 原価計 | F4: 粗利 | G4: 広告費 | H4: 限界利益 | I4: 固定費 | J4: 営業利益 | K4: 注記
A5: M1 | B5: ='02_Assumptions'!$B$70 -> 67 | C5: ='02_Assumptions'!$B$59 -> 26700 | D5: =B5*C5 -> 1788900 | E5: =B5*('02_Assumptions'!$B$60+'02_Assumptions'!$B$13+'02_Assumptions'!$B$59*'02_Assumptions'!$B$12+'02_Assumptions'!$B$14+'02_Assumptions'!$B$16+'02_Assumptions'!$B$17) -> 1270856 | F5: =D5-E5 -> 518044 | G5: =B5*'02_Assumptions'!$B$18 -> 301500 | H5: =F5-G5 -> 216544 | I5: ='02_Assumptions'!$B$57 -> 420750 | J5: =H5-I5 -> -204206 | K5: 月58個＝800個÷12ヶ月
A6: M2 | B6: ='02_Assumptions'!$B$70 -> 67 | C6: ='02_Assumptions'!$B$59 -> 26700 | D6: =B6*C6 -> 1788900 | E6: =B6*('02_Assumptions'!$B$60+'02_Assumptions'!$B$13+'02_Assumptions'!$B$59*'02_Assumptions'!$B$12+'02_Assumptions'!$B$14+'02_Assumptions'!$B$16+'02_Assumptions'!$B$17) -> 1270856 | F6: =D6-E6 -> 518044 | G6: =B6*'02_Assumptions'!$B$18 -> 301500 | H6: =F6-G6 -> 216544 | I6: ='02_Assumptions'!$B$57 -> 420750 | J6: =H6-I6 -> -204206
A7: M3 | B7: ='02_Assumptions'!$B$70 -> 67 | C7: ='02_Assumptions'!$B$59 -> 26700 | D7: =B7*C7 -> 1788900 | E7: =B7*('02_Assumptions'!$B$60+'02_Assumptions'!$B$13+'02_Assumptions'!$B$59*'02_Assumptions'!$B$12+'02_Assumptions'!$B$14+'02_Assumptions'!$B$16+'02_Assumptions'!$B$17) -> 1270856 | F7: =D7-E7 -> 518044 | G7: =B7*'02_Assumptions'!$B$18 -> 301500 | H7: =F7-G7 -> 216544 | I7: ='02_Assumptions'!$B$57 -> 420750 | J7: =H7-I7 -> -204206
A8: M4 | B8: ='02_Assumptions'!$B$70 -> 67 | C8: ='02_Assumptions'!$B$59 -> 26700 | D8: =B8*C8 -> 1788900 | E8: =B8*('02_Assumptions'!$B$60+'02_Assumptions'!$B$13+'02_Assumptions'!$B$59*'02_Assumptions'!$B$12+'02_Assumptions'!$B$14+'02_Assumptions'!$B$16+'02_Assumptions'!$B$17) -> 1270856 | F8: =D8-E8 -> 518044 | G8: =B8*'02_Assumptions'!$B$18 -> 301500 | H8: =F8-G8 -> 216544 | I8: ='02_Assumptions'!$B$57 -> 420750 | J8: =H8-I8 -> -204206
A9: M5 | B9: ='02_Assumptions'!$B$70 -> 67 | C9: ='02_Assumptions'!$B$59 -> 26700 | D9: =B9*C9 -> 1788900 | E9: =B9*('02_Assumptions'!$B$60+'02_Assumptions'!$B$13+'02_Assumptions'!$B$59*'02_Assumptions'!$B$12+'02_Assumptions'!$B$14+'02_Assumptions'!$B$16+'02_Assumptions'!$B$17) -> 1270856 | F9: =D9-E9 -> 518044 | G9: =B9*'02_Assumptions'!$B$18 -> 301500 | H9: =F9-G9 -> 216544 | I9: ='02_Assumptions'!$B$57 -> 420750 | J9: =H9-I9 -> -204206
A10: M6 | B10: ='02_Assumptions'!$B$70 -> 67 | C10: ='02_Assumptions'!$B$59 -> 26700 | D10: =B10*C10 -> 1788900 | E10: =B10*('02_Assumptions'!$B$60+'02_Assumptions'!$B$13+'02_Assumptions'!$B$59*'02_Assumptions'!$B$12+'02_Assumptions'!$B$14+'02_Assumptions'!$B$16+'02_Assumptions'!$B$17) -> 1270856 | F10: =D10-E10 -> 518044 | G10: =B10*'02_Assumptions'!$B$18 -> 301500 | H10: =F10-G10 -> 216544 | I10: ='02_Assumptions'!$B$57 -> 420750 | J10: =H10-I10 -> -204206
A11: M7 | B11: ='02_Assumptions'!$B$70 -> 67 | C11: ='02_Assumptions'!$B$59 -> 26700 | D11: =B11*C11 -> 1788900 | E11: =B11*('02_Assumptions'!$B$60+'02_Assumptions'!$B$13+'02_Assumptions'!$B$59*'02_Assumptions'!$B$12+'02_Assumptions'!$B$14+'02_Assumptions'!$B$16+'02_Assumptions'!$B$17) -> 1270856 | F11: =D11-E11 -> 518044 | G11: =B11*'02_Assumptions'!$B$18 -> 301500 | H11: =F11-G11 -> 216544 | I11: ='02_Assumptions'!$B$57 -> 420750 | J11: =H11-I11 -> -204206
A12: M8 | B12: ='02_Assumptions'!$B$70 -> 67 | C12: ='02_Assumptions'!$B$59 -> 26700 | D12: =B12*C12 -> 1788900 | E12: =B12*('02_Assumptions'!$B$60+'02_Assumptions'!$B$13+'02_Assumptions'!$B$59*'02_Assumptions'!$B$12+'02_Assumptions'!$B$14+'02_Assumptions'!$B$16+'02_Assumptions'!$B$17) -> 1270856 | F12: =D12-E12 -> 518044 | G12: =B12*'02_Assumptions'!$B$18 -> 301500 | H12: =F12-G12 -> 216544 | I12: ='02_Assumptions'!$B$57 -> 420750 | J12: =H12-I12 -> -204206
A13: M9 | B13: ='02_Assumptions'!$B$70 -> 67 | C13: ='02_Assumptions'!$B$59 -> 26700 | D13: =B13*C13 -> 1788900 | E13: =B13*('02_Assumptions'!$B$60+'02_Assumptions'!$B$13+'02_Assumptions'!$B$59*'02_Assumptions'!$B$12+'02_Assumptions'!$B$14+'02_Assumptions'!$B$16+'02_Assumptions'!$B$17) -> 1270856 | F13: =D13-E13 -> 518044 | G13: =B13*'02_Assumptions'!$B$18 -> 301500 | H13: =F13-G13 -> 216544 | I13: ='02_Assumptions'!$B$57 -> 420750 | J13: =H13-I13 -> -204206
A14: M10 | B14: ='02_Assumptions'!$B$70 -> 67 | C14: ='02_Assumptions'!$B$59 -> 26700 | D14: =B14*C14 -> 1788900 | E14: =B14*('02_Assumptions'!$B$60+'02_Assumptions'!$B$13+'02_Assumptions'!$B$59*'02_Assumptions'!$B$12+'02_Assumptions'!$B$14+'02_Assumptions'!$B$16+'02_Assumptions'!$B$17) -> 1270856 | F14: =D14-E14 -> 518044 | G14: =B14*'02_Assumptions'!$B$18 -> 301500 | H14: =F14-G14 -> 216544 | I14: ='02_Assumptions'!$B$57 -> 420750 | J14: =H14-I14 -> -204206
A15: M11 | B15: ='02_Assumptions'!$B$70 -> 67 | C15: ='02_Assumptions'!$B$59 -> 26700 | D15: =B15*C15 -> 1788900 | E15: =B15*('02_Assumptions'!$B$60+'02_Assumptions'!$B$13+'02_Assumptions'!$B$59*'02_Assumptions'!$B$12+'02_Assumptions'!$B$14+'02_Assumptions'!$B$16+'02_Assumptions'!$B$17) -> 1270856 | F15: =D15-E15 -> 518044 | G15: =B15*'02_Assumptions'!$B$18 -> 301500 | H15: =F15-G15 -> 216544 | I15: ='02_Assumptions'!$B$57 -> 420750 | J15: =H15-I15 -> -204206
A16: M12 | B16: ='02_Assumptions'!$B$70 -> 67 | C16: ='02_Assumptions'!$B$59 -> 26700 | D16: =B16*C16 -> 1788900 | E16: =B16*('02_Assumptions'!$B$60+'02_Assumptions'!$B$13+'02_Assumptions'!$B$59*'02_Assumptions'!$B$12+'02_Assumptions'!$B$14+'02_Assumptions'!$B$16+'02_Assumptions'!$B$17) -> 1270856 | F16: =D16-E16 -> 518044 | G16: =B16*'02_Assumptions'!$B$18 -> 301500 | H16: =F16-G16 -> 216544 | I16: ='02_Assumptions'!$B$57 -> 420750 | J16: =H16-I16 -> -204206
A17: 年計 | B17: =SUM(B5:B16) -> 804 | C17: ='02_Assumptions'!$B$59 -> 26700 | D17: =SUM(D5:D16) -> 21466800 | E17: =SUM(E5:E16) -> 15250272 | F17: =SUM(F5:F16) -> 6216528 | G17: =SUM(G5:G16) -> 3618000 | H17: =SUM(H5:H16) -> 2598528 | I17: =SUM(I5:I16) -> 5049000 | J17: =SUM(J5:J16) -> -2450472 | K17: 完売しても年間営業赤字
A18: 注記
A19: この計画は「800個を全て売り切った」最良の消化ケース。それでも営業利益は年 −3,299,952円（通関費2,919円/個を算入後）。
A20: 黒字化には月168個（年2,016個）が必要。800個/年では数量が約3分の1しかない。
A21: ★実績販売数が判明次第、B列を実績で置き換えること。

Sheet 08_Advertising
A1: 広告計画（仮）
A2: ★実績データ未提出のため、CPC60円・CVR1.0%を仮置きした媒体別の計画値です。各媒体の管理画面の実績で差し替えてください。
A4: ① 媒体別 計画（月次・仮）
A5: 媒体 | B5: 予算配分 | C5: 広告費(円) | D5: CPM(円) | E5: Imp | F5: CTR | G5: Click | H5: CPC(円) | I5: LP到達率 | J5: LP View | K5: CVR | L5: CV | M5: CPA(円) | N5: 注記
A6: Meta | B6: 0.45 | C6: ='02_Assumptions'!$B$46*'02_Assumptions'!$B$5*B6 -> 196020 | D6: 1500 | E6: =C6/D6*1000 -> 130680 | F6: 0.012 | G6: =E6*F6 -> 1568.16 | H6: =C6/G6 -> 125 | I6: 0.9 | J6: =G6*I6 -> 1411.344 | K6: 0.01 | L6: =J6*K6 -> 14.11344 | M6: =IF(L6=0,0,C6/L6) -> 13888.889 | N6: 韓国Meta。最も配信量が取れる想定
A7: Google（検索+P-MAX） | B7: 0.2 | C7: ='02_Assumptions'!$B$46*'02_Assumptions'!$B$5*B7 -> 87120 | D7: 2000 | E7: =C7/D7*1000 -> 43560 | F7: 0.02 | G7: =E7*F7 -> 871.2 | H7: =C7/G7 -> 100 | I7: 0.9 | J7: =G7*I7 -> 784.08 | K7: 0.015 | L7: =J7*K7 -> 11.7612 | M7: =IF(L7=0,0,C7/L7) -> 7407.4074 | N7: 指名+一般キーワード。CVRは高めだが量が出にくい
A8: ネイバーGFA/検索 | B8: 0.2 | C8: ='02_Assumptions'!$B$46*'02_Assumptions'!$B$5*B8 -> 87120 | D8: 1200 | E8: =C8/D8*1000 -> 72600 | F8: 0.01 | G8: =E8*F8 -> 726 | H8: =C8/G8 -> 120 | I8: 0.95 | J8: =G8*I8 -> 689.7 | K8: 0.012 | L8: =J8*K8 -> 8.2764 | M8: =IF(L8=0,0,C8/L8) -> 10526.316 | N8: モール内導線が短くCVRは高め
A9: クーパン広告 | B9: 0.1 | C9: ='02_Assumptions'!$B$46*'02_Assumptions'!$B$5*B9 -> 43560 | D9: 1000 | E9: =C9/D9*1000 -> 43560 | F9: 0.015 | G9: =E9*F9 -> 653.4 | H9: =C9/G9 -> 66.666667 | I9: 1 | J9: =G9*I9 -> 653.4 | K9: 0.008 | L9: =J9*K9 -> 5.2272 | M9: =IF(L9=0,0,C9/L9) -> 8333.3333 | N9: モール内広告。在庫再登録後に開始
A10: インフルエンサー/PR | B10: 0.05 | C10: ='02_Assumptions'!$B$46*'02_Assumptions'!$B$5*B10 -> 21780 | N10: CPA計測が難しい。認知目的
A11: 合計 | B11: =SUM(B6:B10) -> 1 | C11: =SUM(C6:C10) -> 435600 | L11: =SUM(L6:L10) -> 39.37824 | M11: =C11/L11 -> 11061.947 | N11: ★広告のみでの獲得
A13: ② 判定：この計画は成立するか
A14: 指標 | B14: 計画値 | C14: 社内基準 | D14: 判定
A15: 加重平均CPA | B15: 11061.947 | C15: 目標¥4,500 / 許容¥6,000 | D15: ✕ 未達
A16: MIX限界利益（@計画CPA） | B16: -3329.9469 | C16: プラスであること | D16: ✕ 未達
A17: 限界利益ROAS | B17: 0.6989728 | C17: 1.0超 | D17: ✕ 未達
A18: 月間CV数 | B18: 39.37824 | C18: 損益分岐 131個/月 | D18: ✕ 未達
A19: 広告費率（広告費÷売上） | B19: 0.41430513 | C19: 目標15% / 許容20% | D19: ✕ 未達
A21: ③ 実績入力欄（日次・差し替え用）
A22: 日付 | B22: 媒体 | C22: 広告費 | D22: Imp | E22: CPM | F22: Click | G22: CTR | H22: CPC | I22: LP View | J22: CVR | K22: CV | L22: CPA | M22: 売上 | N22: 限界利益ROAS
A29: 注記
A30: ★計画CPA（加重平均 ¥11,062）は社内の許容上限¥6,000を超えています。CPC・CVRの仮値が楽観的すぎるか、目標CPAが高すぎるかのどちらかです。
A31: ★MIX限界利益 ¥7,732 に対しCPAが ¥11,062 のため、1個売るごとに ¥-3,330 の赤字です。
A32: 限界利益ROAS ＝ 粗利 ÷ 広告費。1.0を割ったら、売上が伸びていても赤字。ROAS（売上ベース）単独で黒字判断しないこと。
A33: ★差し替え先：Meta広告マネージャ／Google広告／ネイバー検索広告・GFA／クーパン広告 の各管理画面。

Sheet 09_Funnel
A1: ファネル（仮）
A2: ★実数未提出。業界ベンチマークで仮置きした月次ファネルです。各媒体＋モール管理画面の実数で差し替えてください。
A4: ① 月次ファネル（仮・広告稼働時）
A5: 段階 | B5: 母数 | C5: CV数 | D5: CVR | E5: 業界目安 | F5: 自社実績 | G5: 責任者 | H5: ボトルネック判定
A6: 認知（Imp） | C6: 290400 | D6: — | E6: — | F6: — | G6: 要任命
A7: クリック | B7: 290400 | C7: 3775.2 | D7: 0.013 | E7: 1.0〜2.0% | F7: — | G7: 要任命
A8: LP/商品ページ到達 | B8: 3775.2 | C8: 3397.68 | D8: 0.9 | E8: 85〜95% | F8: — | G8: 要任命
A9: カート投入 | B9: 3397.68 | C9: 169.884 | D9: 0.05 | E9: 3〜8% | F9: — | G9: 要任命
A10: 購入・予約 | B10: 169.884 | C10: 37.37448 | D10: 0.22 | E10: 20〜30% | F10: 0.0% | G10: 要任命 | H10: ★最大の落ち込み
A11: 入金完了 | B11: 37.37448 | C11: 35.505756 | D11: 0.95 | E11: 93〜98% | F11: — | G11: 要任命
A12: レビュー投稿 | B12: 35.505756 | C12: 8.876439 | D12: 0.25 | E12: 15〜30% | F12: — | G12: 要任命 | H12: 累計25件
A13: 12ヶ月内リピート | B13: — | C13: — | D13: 0.03 | E13: 低頻度商材 | F13: — | G13: 要任命 | H13: 買替7年
A14: 紹介 | B14: — | C14: — | D14: 0.01 | E14: — | F14: — | G14: 要任命
A16: ② ボトルネックと打ち手
A17: 順位 | B17: 段階 | C17: 現状（仮） | D17: 目標 | E17: 改善余地 | F17: 打ち手 | G17: 担当 | H17: 期限
A18: 1 | B18: LP→カート投入 | C18: 5.0% | D18: 8.0% | E18: +60% | F18: サイズ比較動画・実測重量・容量の見える化・返品ポリシー明記 | G18: 要任命 | H18: 10/10
A19: 2 | B19: カート→購入 | C19: 22% | D19: 30% | E19: +36% | F19: カート離脱リマインド・送料無料ライン・分割払い表示 | G19: 要任命 | H19: 10/20
A20: 3 | B20: クリック→LP | C20: 90% | D20: 95% | E20: +6% | F20: 表示速度改善・遷移先の一致 | G20: 要任命 | H20: 10/31
A21: 4 | B21: Imp→クリック | C21: 1.3% | D21: 1.8% | E21: +38% | F21: クリエイティブ3本以上のA/B・訴求軸の変更 | G21: 要任命 | H21: 10/10
A22: 注記
A23: ★実績は「訪問1,207件・新規購入0件」のみ。上記の段階別CVRは全て業界ベンチマークによる仮値です。
A24: ★まず測ること：ネイバー/クーパンの管理画面から ①商品ページ閲覧数 ②カート投入数 ③購入数 を日次で取得し、この表のB・C列を実数で埋める。
A25: ボトルネックが特定できるまで広告費は増やさない。仮に1位のLP→カートが正しければ、同じ広告費で購入数が1.6倍になる。

Sheet 10_P&L
A1: 損益計算（年間・3シナリオ）
A2: 営業利益がマイナス＝売っても固定費を回収できていない。悲観から先に見る。
A4: 項目 | B4: 悲観 | C4: 標準 | D4: 楽観 | E4: 注記
A5: 年間販売数 | B5: =ROUND('02_Assumptions'!$B$70*'02_Assumptions'!$B$29,0)*12 -> 408 | C5: ='02_Assumptions'!$B$70*12 -> 804 | D5: =ROUND('02_Assumptions'!$B$70*'02_Assumptions'!$B$31,0)*12 -> 1200 | E5: 悲観=標準50% / 楽観=標準150%
A6: CPA | B6: ='02_Assumptions'!$B$18*'02_Assumptions'!$B$30 -> 6750 | C6: ='02_Assumptions'!$B$18 -> 4500 | D6: ='02_Assumptions'!$B$18*'02_Assumptions'!$B$32 -> 3600 | E6: 悲観150% / 標準=社内目標 / 楽観80%
A7: 売上高 | B7: =B5*'02_Assumptions'!$B$59 -> 10893600 | C7: =C5*'02_Assumptions'!$B$59 -> 21466800 | D7: =D5*'02_Assumptions'!$B$59 -> 32040000 | E7: 平均単価26,700円×数量
A8: 売上原価（原価+送料+手数料） | B8: =B5*('02_Assumptions'!$B$60+'02_Assumptions'!$B$13+'02_Assumptions'!$B$59*'02_Assumptions'!$B$12+'02_Assumptions'!$B$14+'02_Assumptions'!$B$16+'02_Assumptions'!$B$17) -> 7738944 | C8: =C5*('02_Assumptions'!$B$60+'02_Assumptions'!$B$13+'02_Assumptions'!$B$59*'02_Assumptions'!$B$12+'02_Assumptions'!$B$14+'02_Assumptions'!$B$16+'02_Assumptions'!$B$17) -> 15250272 | D8: =D5*('02_Assumptions'!$B$60+'02_Assumptions'!$B$13+'02_Assumptions'!$B$59*'02_Assumptions'!$B$12+'02_Assumptions'!$B$14+'02_Assumptions'!$B$16+'02_Assumptions'!$B$17) -> 22761600 | E8: ★関税・国際送料・倉庫・返品は未算入
A9: 売上総利益（粗利） | B9: =B7-B8 -> 3154656 | C9: =C7-C8 -> 6216528 | D9: =D7-D8 -> 9278400 | E9: 粗利率37.2%
A10: 広告宣伝費 | B10: =B5*B6 -> 2754000 | C10: =C5*C6 -> 3618000 | D10: =D5*D6 -> 4320000
A11: 限界利益 | B11: =B9-B10 -> 400656 | C11: =C9-C10 -> 2598528 | D11: =D9-D10 -> 4958400 | E11: 粗利 − 広告費
A12: 固定費 | B12: ='02_Assumptions'!$B$58*12 -> 5555065.6 | C12: ='02_Assumptions'!$B$57*12 -> 5049000 | D12: ='02_Assumptions'!$B$57*12 -> 5049000 | E12: 悲観のみ実績平均を使用
A13: 営業利益 | B13: =B11-B12 -> -5154409.6 | C13: =C11-C12 -> -2450472 | D13: =D11-D12 -> -90600 | E13: ★標準ケースでも赤字
A14: 営業利益率 | B14: =B13/B7 -> -0.47315943 | C14: =C13/C7 -> -0.11415171 | D14: =D13/D7 -> -0.0028277154
A15: 注記
A16: 標準ケース（800個を12ヶ月で完売）でも営業利益 −3,299,952円。通関費を実額算入した結果、楽観ケースすら −1,485,828円で赤字。
A17: 黒字化の条件は ①年2,016個以上 ②通関費を1個1,000円以下に下げる ③売価を1個3,000円上げる ④固定費を月25万円以下 のいずれか。単独では足りず複数の同時達成が要る。
A18: ★まだ未算入：返品引当・ポイント/クーポン負担。これらを1,000円/個入れると赤字はさらに拡大する。

Sheet 11_Cash Flow
A1: キャッシュフロー・最大運転資金
A2: 利益が出ても現金が尽きれば終わる。発注→最終入金まで資金が寝る期間を日数で見る。
A4: 資金サイクル（800個ロット）
A5: 工程 | B5: 経過日数 | C5: 支出 | D5: 入金 | E5: 累計残高影響 | F5: 注記
A6: 発注・前金 | B6: 0 | C6: ='02_Assumptions'!$B$71*'02_Assumptions'!$B$33 -> 3696000 | E6: -3696000 | F6: 手元資金から流出
A7: 製造 | B7: 60 | E7: -3696000 | F7: 仮定60日
A8: 残金支払・船積 | B8: 65 | C8: ='02_Assumptions'!$B$71*(1-'02_Assumptions'!$B$33) -> 8624000 | E8: -12320000 | F8: ★ここで最大流出
A9: 海上輸送 | B9: 85 | E9: -12320000 | F9: 仮定20日
A10: 通関・国内入庫 | B10: ='02_Assumptions'!$B$34 -> 90 | E10: -12320000 | F10: 関税・通関費は未算入（要確認）
A11: 販売開始 | B11: 95 | E11: -12320000 | F11: 以降、広告費が毎月発生
A12: 初回入金 | B12: =95+'02_Assumptions'!$B$35 -> 125 | D12: ='02_Assumptions'!$B$70*'02_Assumptions'!$B$59 -> 1788900 | E12: -10531100 | F12: モール締め後
A13: 全量販売完了 | B13: 455 | E13: -10531100 | F13: 月58個ペースで12ヶ月
A14: 最終入金 | B14: 485 | E14: -10531100 | F14: 発注から約16ヶ月
A16: 最大運転資金の推定
A17: 項目 | B17: 金額 | F17: 注記
A18: 800個 仕入原価 | B18: ='02_Assumptions'!$B$71 -> 12320000 | F18: ミックス加重・現行単価。数量割引が取れれば減る
A19: 固定費 3ヶ月分 | B19: ='02_Assumptions'!$B$57*3 -> 1262250 | F19: 販売開始前〜初回入金までの空白
A20: 広告費 3ヶ月分 | B20: ='02_Assumptions'!$B$70*'02_Assumptions'!$B$18*3 -> 904500 | F20: 月58個×CPA4,500
A21: 次回支払い（既定） | B21: 1373395 | F21: マーケ396万W＋今回入荷33個405万W＋固定費等
A22: 関税・国際送料・通関 | B22: ='02_Assumptions'!$B$14*'02_Assumptions'!$B$28 -> 800000 | F22: ★未算入。実額を入れること
A23: 最大運転資金 合計 | B23: =SUM(B18:B22) -> 16660145 | F23: この金額が手元にないと資金ショートする
A25: 過去9ヶ月の総支出 | B25: =37875450*'02_Assumptions'!$B$5 -> 4166299.5 | F25: 比較対象
A26: 倍率 | B26: =B25/B24 -> 3.9987872 | F26: 回収前に先出しする資金の大きさ
A27: 注記
A28: 最大運転資金 約16,660,145円。過去9ヶ月の総支出（約4,166,300円）の4.0倍を、回収前に先出しすることになる。
A29: ★手元キャッシュが未開示。これが最大運転資金を下回るなら、800個発注はその時点で不可能。
A30: 発注から最終入金まで約16ヶ月。この間ずっと資金が寝る。

Sheet 12_Inventory
A1: 在庫分析
A2: 在庫は売れ残れば現金が紙に変わる。消化月数と回転日数で危険度を測る。
A4: 項目 | B4: 悲観(月29個) | C4: 標準(月58個) | D4: 楽観(月87個) | E4: 健全値 | F4: 注記
A5: 800個の消化月数 | B5: ='02_Assumptions'!$B$28/ROUND('02_Assumptions'!$B$70*'02_Assumptions'!$B$29,0) -> 23.529412 | C5: ='02_Assumptions'!$B$28/'02_Assumptions'!$B$70 -> 11.940299 | D5: ='02_Assumptions'!$B$28/ROUND('02_Assumptions'!$B$70*'02_Assumptions'!$B$31,0) -> 8 | E5: ≤6ヶ月 | F5: 12ヶ月超＝型落ちリスク
A6: 在庫回転日数 | B6: ='02_Assumptions'!$B$28/ROUND('02_Assumptions'!$B$70*'02_Assumptions'!$B$29,0)*30 -> 705.88235 | C6: ='02_Assumptions'!$B$28/'02_Assumptions'!$B$70*30 -> 358.20896 | D6: ='02_Assumptions'!$B$28/ROUND('02_Assumptions'!$B$70*'02_Assumptions'!$B$31,0)*30 -> 240 | E6: 60〜90日 | F6: EC物販の健全値は60〜90日
A7: 滞留在庫（12ヶ月後） | B7: =MAX(0,'02_Assumptions'!$B$28-ROUND('02_Assumptions'!$B$70*'02_Assumptions'!$B$29,0)*12) -> 392 | C7: =MAX(0,'02_Assumptions'!$B$28-'02_Assumptions'!$B$70*12) -> 0 | D7: =MAX(0,'02_Assumptions'!$B$28-ROUND('02_Assumptions'!$B$70*'02_Assumptions'!$B$31,0)*12) -> 0 | E7: 0個 | F7: 悲観では352個が残る
A8: 滞留在庫の評価額 | B8: =MAX(0,'02_Assumptions'!$B$28-ROUND('02_Assumptions'!$B$70*'02_Assumptions'!$B$29,0)*12)*'02_Assumptions'!$B$60 -> 6036800 | C8: =MAX(0,'02_Assumptions'!$B$28-'02_Assumptions'!$B$70*12)*'02_Assumptions'!$B$60 -> 0 | D8: =MAX(0,'02_Assumptions'!$B$28-ROUND('02_Assumptions'!$B$70*'02_Assumptions'!$B$31,0)*12)*'02_Assumptions'!$B$60 -> 0 | E8: ¥0 | F8: ★半額処分ならこの半分が損失
A9: 半額処分時の損失 | B9: =MAX(0,'02_Assumptions'!$B$28-ROUND('02_Assumptions'!$B$70*'02_Assumptions'!$B$29,0)*12)*'02_Assumptions'!$B$60*0.5 -> 3018400 | C9: =MAX(0,'02_Assumptions'!$B$28-'02_Assumptions'!$B$70*12)*'02_Assumptions'!$B$60*0.5 -> 0 | D9: =MAX(0,'02_Assumptions'!$B$28-ROUND('02_Assumptions'!$B$70*'02_Assumptions'!$B$31,0)*12)*'02_Assumptions'!$B$60*0.5 -> 0 | E9: ¥0 | F9: 在庫リスクの実額
A10: 現行在庫33個の消化月数 | B10: =33/ROUND('02_Assumptions'!$B$70*'02_Assumptions'!$B$29,0) -> 0.97058824 | C10: =33/'02_Assumptions'!$B$70 -> 0.49253731 | D10: =33/ROUND('02_Assumptions'!$B$70*'02_Assumptions'!$B$31,0) -> 0.33 | E10: — | F10: 今回入荷分
A12: 800個は現行入荷33個の何倍か | B12: ='02_Assumptions'!$B$28/33 -> 24.242424 | E12: 倍 | F12: ★実績データなしで21倍の在庫を持つことになる
A13: 注記
A14: ★800個は現在の入荷ペース（33個）の21倍。販売実績が未提出のまま21倍の在庫を持つのは承認できない。
A15: スーツケースは色・型番の陳腐化が早く、滞留在庫は値引き処分が前提になる。悲観ケースでは約271万円の損失。
A16: 倉庫費が未算入。800個（S/M/L混在）の保管スペースと月額費用を必ず見積もること。
A17: 推奨：一括ではなく100〜150個×複数回の分割発注。単価は上がるが在庫リスクは約1/5になる。

Sheet 13_Scenario
A1: 3シナリオ比較
A2: 悲観ケースで死なないことが投資の最低条件。
A4: 項目 | B4: 悲観 | C4: 標準 | D4: 楽観 | E4: 前提・注記
A5: 月販売数 | B5: ='10_P&L'!B5/12 -> 34 | C5: ='10_P&L'!C5/12 -> 67 | D5: ='10_P&L'!D5/12 -> 100 | E5: 標準=800個÷12ヶ月
A6: CPA | B6: ='10_P&L'!B6 -> 6750 | C6: ='10_P&L'!C6 -> 4500 | D6: ='10_P&L'!D6 -> 3600 | E6: 悲観150%/標準=目標/楽観80%
A7: 年間売上 | B7: ='10_P&L'!B7 -> 10893600 | C7: ='10_P&L'!C7 -> 21466800 | D7: ='10_P&L'!D7 -> 32040000
A8: 年間粗利 | B8: ='10_P&L'!B9 -> 3154656 | C8: ='10_P&L'!C9 -> 6216528 | D8: ='10_P&L'!D9 -> 9278400
A9: 年間広告費 | B9: ='10_P&L'!B10 -> 2754000 | C9: ='10_P&L'!C10 -> 3618000 | D9: ='10_P&L'!D10 -> 4320000
A10: 年間限界利益 | B10: ='10_P&L'!B11 -> 400656 | C10: ='10_P&L'!C11 -> 2598528 | D10: ='10_P&L'!D11 -> 4958400
A11: 年間固定費 | B11: ='10_P&L'!B12 -> 5555065.6 | C11: ='10_P&L'!C12 -> 5049000 | D11: ='10_P&L'!D12 -> 5049000 | E11: 悲観のみ実績平均
A12: 年間営業利益 | B12: ='10_P&L'!B13 -> -5154409.6 | C12: ='10_P&L'!C13 -> -2450472 | D12: ='10_P&L'!D13 -> -90600 | E12: ★標準でも赤字
A13: 営業利益率 | B13: ='10_P&L'!B14 -> -0.47315943 | C13: ='10_P&L'!C14 -> -0.11415171 | D13: ='10_P&L'!D14 -> -0.0028277154
A14: 注記
A15: 悲観ケースの年間赤字 −5,463,542円。過去9ヶ月の総支出（417万円）を1年で吹き飛ばす規模。
A16: ★通関費を実額算入した結果、楽観ケース（月87個・CPA3,600円）ですら −1,485,828円の赤字。3シナリオすべてで黒字にならない。
A17: 投資判断の原則：全シナリオで赤字の事業に大型投資はしない。まず単位あたりの採算を成立させること。

Sheet 14_Risk
A1: リスク登録簿（24件）
A2: Score = 発生確率 × 影響度（各1〜5）。Score20以上（赤）は投資前に潰す。上位には必ず対策と責任者。
A4: No | B4: リスク | C4: 分類 | D4: 発生確率 | E4: 影響度 | F4: Score | G4: 予防策 | H4: 発生時対応 | I4: 責任者
A5: 1 | B5: 800個が売れ残り滞留在庫化する | C5: 在庫 | D5: 5 | E5: 5 | F5: =D5*E5 -> 25 | G5: 分割発注に切替／予約販売で需要を先に取る | H5: 値引き処分＋B2B卸・アウトレット放出 | I5: 北野
A6: 2 | B6: 販売実績データが無いまま投資し前提が全て外れる | C6: 市場 | D6: 5 | E6: 5 | F6: =D6*E6 -> 25 | G6: MVPで30日実測してから次の投資 | H6: Gate未達なら発注しない | I6: 北野
A7: 3 | B7: 手元キャッシュが最大運転資金1,420万円に届かない | C7: キャッシュ | D7: 4 | E7: 5 | F7: =D7*E7 -> 20 | G7: 発注前に資金繰り表を作成／分割発注で山を下げる | H7: 発注延期。借入は限界利益黒字化後 | I7: 北野
A8: 4 | B8: モール手数料が実際は10〜15%で限界利益が消える | C8: 価格 | D8: 4 | E8: 5 | F8: =D8*E8 -> 20 | G8: 各モールの実手数料を契約書で確認 | H8: 価格改定または該当モール撤退 | I8: 要任命
A9: 5 | B9: 関税・国際送料・倉庫費が未算入で採算が崩れる | C9: 物流 | D9: 4 | E9: 4 | F9: =D9*E9 -> 16 | G9: 通関業者・3PLに事前見積 | H9: 売価改定／原価交渉 | I9: 要任命
A10: 6 | B10: 競合が同型番の廉価版を投入し価格競争になる | C10: 競合 | D10: 4 | E10: 4 | F10: =D10*E10 -> 16 | G10: 意匠登録／レビュー資産の先行構築 | H10: 価格では追わずバンドル・保証で差別化 | I10: 北野
A11: 7 | B11: 固定費（月382万W）が売上に先行して膨らむ | C11: キャッシュ | D11: 4 | E11: 4 | F11: =D11*E11 -> 16 | G11: 黒字化まで固定費を増やさない | H11: 人件費・家賃の見直し | I11: 北野
A12: 8 | B12: 広告依存度が高く広告停止で売上がゼロになる | C12: 広告 | D12: 4 | E12: 4 | F12: =D12*E12 -> 16 | G12: オーガニック比率を計測・KPI化 | H12: SEO/SNSへ段階的にシフト | I12: 要任命
A13: 9 | B13: サンクコスト（既払マーケ費・既存在庫）で判断が歪む | C13: 組織 | D13: 4 | E13: 4 | F13: =D13*E13 -> 16 | G13: Kill Criteriaを事前に文書化 | H13: 既払費用は判断材料から除外 | I13: 北野
A14: 10 | B14: CPAが許容上限6,000円を超え広告が回らない | C14: 広告 | D14: 3 | E14: 5 | F14: =D14*E14 -> 15 | G14: 小ロットで実CPAを測定してから増資 | H14: 広告停止→オーガニック検証に切替 | I14: 要任命
A15: 11 | B15: 為替が円安に振れ原価が上昇する | C15: 為替 | D15: 3 | E15: 4 | F15: =D15*E15 -> 12 | G15: 為替予約／複数回に分けて発注 | H15: 売価改定 | I15: 北野
A16: 12 | B16: 返品率が想定を超える（大型商品は返送料が高い） | C16: 品質 | D16: 3 | E16: 4 | F16: =D16*E16 -> 12 | G16: 返品ポリシー明記／サイズ比較コンテンツ | H16: 返品理由を分類し商品改善 | I16: 要任命
... A28: 24 | B28: 韓国法人→日本販売の税務・移転価格の指摘 | C28: 税務 | D28: 2 | E28: 4 | F28: =D28*E28 -> 8 | G28: 税理士に事前確認 | H28: 修正申告 | I28: 税理士
A29: 注記
A30: Score20以上（赤）は投資前に潰すべきリスク。うち3件は「データが無いこと」そのものが原因＝Gate0で解消できる。
A31: 「要任命」の責任者は空欄のままにしない。1名を必ず指名すること。

Sheet 15_MVP
A1: MVP設計と投資ゲート
A2: 大規模投資の前に最小費用で「需要・価格・CVR・CPA」を実測する。Gate未達なら次の金を出さない。
A4: MVP（最小検証）
A5: No | B5: 検証内容 | C5: 費用 | D5: 期間 | E5: 方法 | F5: 責任者
A6: 1 | B6: L の予約販売で実需を測る | C6: ¥0 | D6: 14日 | E6: 在庫ゼロのまま予約ページを公開。予約数＝実需。キャッシュを使わない最強の検証 | F6: 北野
A7: 2 | B7: モール実手数料の確認 | C7: ¥0 | D7: 3日 | E7: 楽天・Amazon・自社ECの契約書と精算レポートから実負担率を算出 | F7: 北野
A8: 3 | B8: 関税・国際送料・倉庫の実見積 | C8: ¥0 | D8: 7日 | E8: 通関業者・3PLに800個ベースで見積依頼 | F8: 要任命
A9: 4 | B9: 過去の販売実績・CPA・CVRを集計 | C9: ¥0 | D9: 5日 | E9: キントーン＋各媒体レポートからSKU別・媒体別の月次実績を出す | F9: 要任命
A10: 5 | B10: 800個の仕入単価を交渉 | C10: ¥0 | D10: 14日 | E10: 数量別単価の書面回答を取る。▲20%で損益分岐78→50個 | F10: 北野
A11: 6 | B11: 価格弾力性テスト | C11: ¥0 | D11: 14日 | E11: S を21,900／24,900の2価格でA/B。CVR差分を見る | F11: 要任命
A12: 7 | B12: 広告テスト | C12: ¥150,000 | D12: 30日 | E12: Meta+Google 日額5,000円。CV数・CPA・CVRを実測 | F12: 要任命
A14: 投資ゲート（条件を全て満たすまで次に進まない）
A15: Gate | B15: 投資額 | C15: 突破条件 | D15: 期限 | E15: 未達の場合 | F15: 責任者
A16: Gate0 | B16: ¥0 | C16: 実手数料・関税/倉庫費・手元キャッシュ・800個数量割引単価・過去実績 の5点が全て数値で確定 | D16: 9/18 | E16: 800個発注を白紙に戻す | F16: 北野
A17: Gate1 | B17: ¥150,000 | C17: 30日で CV≥10件 かつ CPA≤¥6,000 かつ CVR≥0.8% | D17: 10/11 | E17: 広告停止。商品・LPを作り直す | F17: 要任命
A18: Gate2 | B18: ¥500,000 | C18: 60日で CPA≤¥4,500 かつ 月販≥30個 かつ 返品率≤5% | D18: 11/10 | E18: Gate1に戻す。追加投資しない | F18: 要任命
A19: Gate3 | B19: ¥1,000,000 | C19: 90日で 月販≥58個 かつ 限界利益が月次で黒字 | D19: 12/10 | E19: 100個のみ追加発注に縮小 | F19: 北野
A20: Gate4 | B20: ¥2,200,000 | C20: 月販≥78個（損益分岐超）を2ヶ月連続 | D20: 2027/02 | E20: 分割発注を継続。800個は見送り | F20: 北野
A21: Gate5 | B21: 800個 本格発注 | C21: 月販≥100個を3ヶ月連続 かつ 手元キャッシュ≥¥15,000,000 | D21: 条件達成時 | E21: 実行しない | F21: 北野
A23: Kill Criteria（撤退基準・事前確定）
A24: No | B24: 基準 | C24: 判定タイミング
A25: 1 | B25: 30日CPAが¥6,000を超える | C25: Gate1
A26: 2 | B26: 60日CVRが0.8%未満 | C26: Gate2
A27: 3 | B27: 返品率が5%を超える | C27: Gate2
A28: 4 | B28: 広告費50万円投下後も月販30個未満 | C28: Gate2
A29: 5 | B29: 限界利益率が15%未満 | C29: 月次
A30: 6 | B30: 在庫回転が120日を超える | C30: 月次
A31: 7 | B31: 営業赤字が2ヶ月連続 | C31: 月次
A32: 8 | B32: 手元キャッシュが固定費3ヶ月分を下回る | C32: 月次 | F32: 即時停止
A33: 注記
A34: Gate0は費用ゼロ。今日から着手できる。ここを飛ばして発注するのが最悪の選択。
A35: ★現時点の推奨投資上限は Gate4 までの累計 ¥2,200,000（小ロット150個相当）。800個への一括投資は承認しない。
A36: Kill Criteria は経営者の感情で動かさない。事前に文書化し、担当者と共有すること。

Sheet 16_KPI Dashboard
A1: KPIダッシュボード
A2: Daily/Weekly/Monthly を分ける。黄色＝実績入力欄。異常値検知ルールは下部。
A4: 【Daily】
B5: 指標 | C5: 目標 | D5: 許容ライン | E5: 実績 | F5: 判定 | G5: 警告条件・対応
B6: 売上 | C6: — | D6: — | G6: 前日比 −20%で警告
B7: 販売数 | C7: — | D7: — | G7: 前日比 −20%で警告
B8: 広告費 | C8: 日額上限を設定 | D8: — | G8: 上限超過で自動停止
B9: CPA | C9: ¥4,500 | D9: ¥6,000 | G9: +20%で警告
B10: 限界利益ROAS | C10: 2.0以上 | D10: 1.0 | G10: 1.0割れで即停止
B11: CVR | C11: — | D11: — | G11: −20%で警告
B12: 在庫数 | C12: — | D12: — | G12: SKU別。欠品/滞留の両方を見る
A14: 【Weekly】
B15: 指標 | C15: 目標 | D15: 許容ライン | E15: 実績 | F15: 判定 | G15: 警告条件・対応
B16: 粗利率 | C16: 37.2%以上 | D16: — | G16: 低下で警告
B17: 限界利益率 | C17: 20.3%以上 | D17: 15% | G17: 15%割れでKill判定
B18: 広告費率 | C18: 15% | D18: 20% | G18: 20%超で警告
B19: SKU別売上 | C19: — | D19: — | G19: 死にSKUの特定
B20: チャネル別売上 | C20: — | D20: — | G20: 広告依存率を必ず見る
B21: 返品率 | C21: ≤3% | D21: 5% | G21: +30%で警告
B22: レビュー件数/評価 | C22: — | D22: ≥4.0 | G22: 低評価は即対応
B23: 在庫回転日数 | C23: ≤90日 | D23: 120日 | G23: 超過で値引き検討
A25: 【Monthly】
B26: 指標 | C26: 目標 | D26: 許容ライン | E26: 実績 | F26: 判定 | G26: 警告条件・対応
B27: 営業利益 | C27: 黒字 | D27: — | G27: 2ヶ月連続赤字でKill判定
B28: キャッシュ残高 | C28: — | D28: 固定費3ヶ月分 | G28: 下回ったら即時停止
B29: LTV | C29: — | D29: — | G29: 低頻度商材のため初回≒LTV
B30: CAC | C30: ¥4,500 | D30: ¥6,000
B31: LTV/CAC（限界利益ベース） | C31: ≥2.0 | D31: 1.0 | G31: 現状1.2は危険水準
B32: 固定費 | C32: ≤¥420,750 | D32: — | G32: 黒字化まで増やさない
